Workbook

Sheet Ene
C1: Diligencie unicamente las celdas verdes | F1: Total | G1: Comisiones | I1: Resultado | J1: Balance inicial | K1: =+(K2-J2)/J2 -> 0
C2: Ganancia o perdida del mes | F2: =I48*5*F3 -> 0 | G2: =-D48*D3*F3 -> 0 | I2: =(F2*F3)+G2 -> 0 | J2: 1250 | K2: =I2+J2 -> 1250
C3: Comision | D3: 3 | E3: Cant. Contratos | F3: 1
C6: Fecha | D6: Total Trades | E6: #Ganados | F6: #Perdidos | G6: Puntos ganados | H6: Puntos perdidos | I6: Total puntos | J6: % Gan/Per | K6: Promedio ganancia | L6: Promedio pérdida | O6: Notas y comentarios
A8: 1 | B8: Lunes | D8: =+E8+F8 -> 0 | E8: 0 | F8: 0 | G8: 0 | H8: 0 | I8: =G8-H8 -> 0 | J8: =IF(SUM(E8:F8),E8/SUM(E8:F8), 0%) -> 0 | K8: =IF(E8>0, G8/E8,0) -> 0 | L8: =IF(F8>0,H8/F8,0) -> 0 | M8: 0
B9: Martes | D9: =+E9+F9 -> 0 | E9: 0 | F9: 0 | G9: 0 | H9: 0 | I9: =G9-H9 -> 0 | J9: =IF(SUM(E9:F9),E9/SUM(E9:F9), 0%) -> 0 | K9: =IF(E9>0, G9/E9,0) -> 0 | L9: =IF(F9>0,H9/F9,0) -> 0 | M9: 0
B10: Miércoles | C10: 46022 | D10: 0 | E10: 0 | F10: 0 | G10: 0 | H10: 0 | I10: =G10-H10 -> 0 | J10: =IF(SUM(E10:F10),E10/SUM(E10:F10), 0%) -> 0 | K10: =IF(E10>0, G10/E10,0) -> 0 | L10: =IF(F10>0,H10/F10,0) -> 0 | M10: 0
B11: Jueves | C11: =C10+1 -> 46023 | D11: =+E11+F11 -> 0 | E11: 0 | F11: 0 | G11: 0 | H11: 0 | I11: =G11-H11 -> 0 | J11: =IF(SUM(E11:F11),E11/SUM(E11:F11), 0%) -> 0 | K11: =IF(E11>0, G11/E11,0) -> 0 | L11: =IF(F11>0,H11/F11,0) -> 0 | M11: 0
B12: Viernes | C12: =C11+1 -> 46024 | D12: =+E12+F12 -> 0 | E12: 0 | F12: 0 | G12: 0 | H12: 0 | I12: =G12-H12 -> 0 | J12: =IF(SUM(E12:F12),E12/SUM(E12:F12), 0%) -> 0 | K12: =IF(E12>0, G12/E12,0) -> 0 | L12: =IF(F12>0,H12/F12,0) -> 0 | M12: 0
C14: Total semana | D14: =SUM(D8:D12) -> 0 | E14: =SUM(E8:E12) -> 0 | F14: =SUM(F8:F12) -> 0 | G14: =SUM(G8:G12) -> 0 | H14: =SUM(H8:H12) -> 0 | I14: =SUM(I8:I12) -> 0 | J14: =IF(SUM(E14:F14),E14/SUM(E14:F14), 0%) -> 0 | K14: =IF(E14>0, G14/E14,0) -> 0 | L14: =IF(F14>0,H14/F14,0) -> 0 | M14: =SUM(M8:M12) -> 0
A16: 2 | B16: Lunes | C16: =C12+3 -> 46027 | D16: 0 | E16: 0 | F16: 0 | G16: 0 | H16: 0 | I16: =G16-H16 -> 0 | J16: =IF(SUM(E16:F16),E16/SUM(E16:F16), 0%) -> 0 | K16: =IF(E16>0, G16/E16,0) -> 0 | L16: =IF(F16>0,H16/F16,0) -> 0 | M16: 0
B17: Martes | C17: =C16+1 -> 46028 | D17: 0 | E17: 0 | F17: 0 | G17: 0 | H17: 0 | I17: =G17-H17 -> 0 | J17: =IF(SUM(E17:F17),E17/SUM(E17:F17), 0%) -> 0 | K17: =IF(E17>0, G17/E17,0) -> 0 | L17: =IF(F17>0,H17/F17,0) -> 0 | M17: 0
B18: Miércoles | C18: =C17+1 -> 46029 | D18: 0 | E18: 0 | F18: 0 | G18: 0 | H18: 0 | I18: =G18-H18 -> 0 | J18: =IF(SUM(E18:F18),E18/SUM(E18:F18), 0%) -> 0 | K18: =IF(E18>0, G18/E18,0) -> 0 | L18: =IF(F18>0,H18/F18,0) -> 0 | M18: 0
B19: Jueves | C19: =C18+1 -> 46030 | D19: 0 | E19: 0 | F19: 0 | G19: 0 | H19: 0 | I19: =G19-H19 -> 0 | J19: =IF(SUM(E19:F19),E19/SUM(E19:F19), 0%) -> 0 | K19: =IF(E19>0, G19/E19,0) -> 0 | L19: =IF(F19>0,H19/F19,0) -> 0 | M19: 0
B20: Viernes | C20: =C19+1 -> 46031 | D20: 0 | E20: 0 | F20: 0 | G20: 0 | H20: 0 | I20: =G20-H20 -> 0 | J20: =IF(SUM(E20:F20),E20/SUM(E20:F20), 0%) -> 0 | K20: =IF(E20>0, G20/E20,0) -> 0 | L20: =IF(F20>0,H20/F20,0) -> 0 | M20: 0
C22: Total semana | D22: =SUM(D16:D20) -> 0 | E22: =SUM(E16:E20) -> 0 | F22: =SUM(F16:F20) -> 0 | G22: =SUM(G16:G20) -> 0 | H22: =SUM(H16:H20) -> 0 | I22: =SUM(I16:I20) -> 0 | J22: =IF(SUM(E22:F22),E22/SUM(E22:F22), 0%) -> 0 | K22: =IF(E22>0, G22/E22,0) -> 0 | L22: =IF(F22>0,H22/F22,0) -> 0 | M22: =SUM(M16:M20) -> 0
A24: 3 | B24: Lunes | C24: =C20+3 -> 46034 | D24: 0 | E24: 0 | F24: 0 | G24: 0 | H24: 0 | I24: =G24-H24 -> 0 | J24: =IF(SUM(E24:F24),E24/SUM(E24:F24), 0%) -> 0 | K24: =IF(E24>0, G24/E24,0) -> 0 | L24: =IF(F24>0,H24/F24,0) -> 0 | M24: 0
B25: Martes | C25: =C24+1 -> 46035 | D25: 0 | E25: 0 | F25: 0 | G25: 0 | H25: 0 | I25: =G25-H25 -> 0 | J25: =IF(SUM(E25:F25),E25/SUM(E25:F25), 0%) -> 0 | K25: =IF(E25>0, G25/E25,0) -> 0 | L25: =IF(F25>0,H25/F25,0) -> 0 | M25: 0
B26: Miércoles | C26: =C25+1 -> 46036 | D26: 0 | E26: 0 | F26: 0 | G26: 0 | H26: 0 | I26: =G26-H26 -> 0 | J26: =IF(SUM(E26:F26),E26/SUM(E26:F26), 0%) -> 0 | K26: =IF(E26>0, G26/E26,0) -> 0 | L26: =IF(F26>0,H26/F26,0) -> 0 | M26: 0
B27: Jueves | C27: =C26+1 -> 46037 | D27: 0 | E27: 0 | F27: 0 | G27: 0 | H27: 0 | I27: =G27-H27 -> 0 | J27: =IF(SUM(E27:F27),E27/SUM(E27:F27), 0%) -> 0 | K27: =IF(E27>0, G27/E27,0) -> 0 | L27: =IF(F27>0,H27/F27,0) -> 0 | M27: 0
B28: Viernes | C28: =C27+1 -> 46038 | D28: 0 | E28: 0 | F28: 0 | G28: 0 | H28: 0 | I28: =G28-H28 -> 0 | J28: =IF(SUM(E28:F28),E28/SUM(E28:F28), 0%) -> 0 | K28: =IF(E28>0, G28/E28,0) -> 0 | L28: =IF(F28>0,H28/F28,0) -> 0 | M28: 0
C30: Total semana | D30: =SUM(D24:D28) -> 0 | E30: =SUM(E24:E28) -> 0 | F30: =SUM(F24:F28) -> 0 | G30: =SUM(G24:G28) -> 0 | H30: =SUM(H24:H28) -> 0 | I30: =SUM(I24:I28) -> 0 | J30: =IF(SUM(E30:F30),E30/SUM(E30:F30), 0%) -> 0 | K30: =IF(E30>0, G30/E30,0) -> 0 | L30: =IF(F30>0,H30/F30,0) -> 0 | M30: =SUM(M24:M28) -> 0
A32: 4 | B32: Lunes | C32: =C28+3 -> 46041 | D32: 0 | E32: 0 | F32: 0 | G32: 0 | H32: 0 | I32: =G32-H32 -> 0 | J32: =IF(SUM(E32:F32),E32/SUM(E32:F32), 0%) -> 0 | K32: =IF(E32>0, G32/E32,0) -> 0 | L32: =IF(F32>0,H32/F32,0) -> 0 | M32: 0
B33: Martes | C33: =C32+1 -> 46042 | D33: 0 | E33: 0 | F33: 0 | G33: 0 | H33: 0 | I33: =G33-H33 -> 0 | J33: =IF(SUM(E33:F33),E33/SUM(E33:F33), 0%) -> 0 | K33: =IF(E33>0, G33/E33,0) -> 0 | L33: =IF(F33>0,H33/F33,0) -> 0 | M33: 0
B34: Miércoles | C34: =C33+1 -> 46043 | D34: 0 | E34: 0 | F34: 0 | G34: 0 | H34: 0 | I34: =G34-H34 -> 0 | J34: =IF(SUM(E34:F34),E34/SUM(E34:F34), 0%) -> 0 | K34: =IF(E34>0, G34/E34,0) -> 0 | L34: =IF(F34>0,H34/F34,0) -> 0 | M34: 0
B35: Jueves | C35: =C34+1 -> 46044 | D35: 0 | E35: 0 | F35: 0 | G35: 0 | H35: 0 | I35: =G35-H35 -> 0 | J35: =IF(SUM(E35:F35),E35/SUM(E35:F35), 0%) -> 0 | K35: =IF(E35>0, G35/E35,0) -> 0 | L35: =IF(F35>0,H35/F35,0) -> 0 | M35: 0
B36: Viernes | C36: =C35+1 -> 46045 | D36: 0 | E36: 0 | F36: 0 | G36: 0 | H36: 0 | I36: =G36-H36 -> 0 | J36: =IF(SUM(E36:F36),E36/SUM(E36:F36), 0%) -> 0 | K36: =IF(E36>0, G36/E36,0) -> 0 | L36: =IF(F36>0,H36/F36,0) -> 0 | M36: 0
C38: Total semana | D38: =SUM(D32:D36) -> 0 | E38: =SUM(E32:E36) -> 0 | F38: =SUM(F32:F36) -> 0 | G38: =SUM(G32:G36) -> 0 | H38: =SUM(H32:H36) -> 0 | I38: =SUM(I32:I36) -> 0 | J38: =IF(SUM(E38:F38),E38/SUM(E38:F38), 0%) -> 0 | K38: =IF(E38>0, G38/E38,0) -> 0 | L38: =IF(F38>0,H38/F38,0) -> 0 | M38: =SUM(M32:M36) -> 0
B40: Lunes | C40: =C36+3 -> 46048 | D40: 0 | E40: 0 | F40: 0 | G40: 0 | H40: 0 | I40: =G40-H40 -> 0 | J40: =IF(SUM(E40:F40),E40/SUM(E40:F40), 0%) -> 0 | K40: =IF(E40>0, G40/E40,0) -> 0 | L40: =IF(F40>0,H40/F40,0) -> 0
B41: Martes | C41: =C40+1 -> 46049 | D41: 0 | E41: 0 | F41: 0 | G41: 0 | H41: 0 | I41: =G41-H41 -> 0 | J41: =IF(SUM(E41:F41),E41/SUM(E41:F41), 0%) -> 0 | K41: =IF(E41>0, G41/E41,0) -> 0 | L41: =IF(F41>0,H41/F41,0) -> 0
B42: Miércoles | C42: =C41+1 -> 46050 | D42: 0 | E42: 0 | F42: 0 | G42: 0 | H42: 0 | I42: =G42-H42 -> 0 | J42: =IF(SUM(E42:F42),E42/SUM(E42:F42), 0%) -> 0 | K42: =IF(E42>0, G42/E42,0) -> 0 | L42: =IF(F42>0,H42/F42,0) -> 0
B43: Jueves | C43: =C42+1 -> 46051 | D43: 0 | E43: 0 | F43: 0 | G43: 0 | H43: 0 | I43: =G43-H43 -> 0 | J43: =IF(SUM(E43:F43),E43/SUM(E43:F43), 0%) -> 0 | K43: =IF(E43>0, G43/E43,0) -> 0 | L43: =IF(F43>0,H43/F43,0) -> 0
B44: Viernes | C44: =C43+1 -> 46052 | D44: 0 | E44: 0 | F44: 0 | G44: 0 | H44: 0 | I44: =G44-H44 -> 0 | J44: =IF(SUM(E44:F44),E44/SUM(E44:F44), 0%) -> 0 | K44: =IF(E44>0, G44/E44,0) -> 0 | L44: =IF(F44>0,H44/F44,0) -> 0
C46: Total semana | D46: =SUM(D32:D36) -> 0 | E46: =SUM(E32:E36) -> 0 | F46: =SUM(F32:F36) -> 0 | G46: =SUM(G32:G36) -> 0 | H46: =SUM(H32:H36) -> 0 | I46: =SUM(I32:I36) -> 0 | J46: =IF(SUM(E46:F46),E46/SUM(E46:F46), 0%) -> 0 | K46: =IF(E46>0, G46/E46,0) -> 0 | L46: =IF(F46>0,H46/F46,0) -> 0 | M46: =SUM(M32:M36) -> 0
C48: Total mes | D48: =D14+D22+D46+D30 -> 0 | E48: =E14+E22+E46+E30 -> 0 | F48: =F14+F22+F46+F30 -> 0 | G48: =G14+G22+G46+G30 -> 0 | H48: =H14+H22+H46+H30 -> 0 | I48: =I14+I22+I46+I30 -> 0 | J48: =J14+J22+J46+J30+J38 -> 0 | K48: =K14+K22+K46+K30 -> 0 | L48: =L14+L22+L46+L30 -> 0 | M48: =M14+M22+M30+M46+#REF! -> #REF!

Sheet Feb
C1: Diligencie unicamente las celdas verdes | F1: Total | G1: Comisiones | I1: Resultado | J1: Balance inicial | K1: =+(K2-J2)/J2 -> 0
C2: Ganancia o perdida del mes | F2: =I40*5*F3 -> 0 | G2: =-D40*D3*F3 -> 0 | I2: =(F2*F3)+G2 -> 0 | J2: 1250 | K2: =I2+J2 -> 1250
C3: Comision | D3: 3 | E3: Cant. Contratos | F3: 1
C6: Fecha | D6: Total Trades | E6: #Ganados | F6: #Perdidos | G6: Puntos ganados | H6: Puntos perdidos | I6: Total puntos | J6: % Gan/Per | K6: Promedio ganancia | L6: Promedio Perdida | O6: Notas y comentarios
A8: 2 | B8: Lunes | C8: 46055 | D8: 0 | E8: 0 | F8: 0 | G8: 0 | H8: 0 | I8: =G8-H8 -> 0 | J8: =IF(SUM(E8:F8),E8/SUM(E8:F8), 0%) -> 0 | K8: =IF(E8>0, G8/E8,0) -> 0 | L8: =IF(F8>0,H8/F8,0) -> 0 | M8: 0
B9: Martes | C9: =C8+1 -> 46056 | D9: 0 | E9: 0 | F9: 0 | G9: 0 | H9: 0 | I9: =G9-H9 -> 0 | J9: =IF(SUM(E9:F9),E9/SUM(E9:F9), 0%) -> 0 | K9: =IF(E9>0, G9/E9,0) -> 0 | L9: =IF(F9>0,H9/F9,0) -> 0 | M9: 0
B10: Miércoles | C10: =C9+1 -> 46057 | D10: 0 | E10: 0 | F10: 0 | G10: 0 | H10: 0 | I10: =G10-H10 -> 0 | J10: =IF(SUM(E10:F10),E10/SUM(E10:F10), 0%) -> 0 | K10: =IF(E10>0, G10/E10,0) -> 0 | L10: =IF(F10>0,H10/F10,0) -> 0 | M10: 0
B11: Jueves | C11: =C10+1 -> 46058 | D11: 0 | E11: 0 | F11: 0 | G11: 0 | H11: 0 | I11: =G11-H11 -> 0 | J11: =IF(SUM(E11:F11),E11/SUM(E11:F11), 0%) -> 0 | K11: =IF(E11>0, G11/E11,0) -> 0 | L11: =IF(F11>0,H11/F11,0) -> 0 | M11: 0
B12: Viernes | C12: =C11+1 -> 46059 | D12: 0 | E12: 0 | F12: 0 | G12: 0 | H12: 0 | I12: =G12-H12 -> 0 | J12: =IF(SUM(E12:F12),E12/SUM(E12:F12), 0%) -> 0 | K12: =IF(E12>0, G12/E12,0) -> 0 | L12: =IF(F12>0,H12/F12,0) -> 0 | M12: 0
C14: Total semana | D14: =SUM(D8:D12) -> 0 | E14: =SUM(E8:E12) -> 0 | F14: =SUM(F8:F12) -> 0 | G14: =SUM(G8:G12) -> 0 | H14: =SUM(H8:H12) -> 0 | I14: =SUM(I8:I12) -> 0 | J14: =IF(SUM(E14:F14),E14/SUM(E14:F14), 0%) -> 0 | K14: =IF(E14>0, G14/E14,0) -> 0 | L14: =IF(F14>0,H14/F14,0) -> 0 | M14: =SUM(M8:M12) -> 0
A16: 3 | B16: Lunes | C16: =C12+3 -> 46062 | D16: 0 | E16: 0 | F16: 0 | G16: 0 | H16: 0 | I16: =G16-H16 -> 0 | J16: =IF(SUM(E16:F16),E16/SUM(E16:F16), 0%) -> 0 | K16: =IF(E16>0, G16/E16,0) -> 0 | L16: =IF(F16>0,H16/F16,0) -> 0 | M16: 0
B17: Martes | C17: =C16+1 -> 46063 | D17: 0 | E17: 0 | F17: 0 | G17: 0 | H17: 0 | I17: =G17-H17 -> 0 | J17: =IF(SUM(E17:F17),E17/SUM(E17:F17), 0%) -> 0 | K17: =IF(E17>0, G17/E17,0) -> 0 | L17: =IF(F17>0,H17/F17,0) -> 0 | M17: 0
B18: Miércoles | C18: =C17+1 -> 46064 | D18: 0 | E18: 0 | F18: 0 | G18: 0 | H18: 0 | I18: =G18-H18 -> 0 | J18: =IF(SUM(E18:F18),E18/SUM(E18:F18), 0%) -> 0 | K18: =IF(E18>0, G18/E18,0) -> 0 | L18: =IF(F18>0,H18/F18,0) -> 0 | M18: 0
B19: Jueves | C19: =C18+1 -> 46065 | D19: 0 | E19: 0 | F19: 0 | G19: 0 | H19: 0 | I19: =G19-H19 -> 0 | J19: =IF(SUM(E19:F19),E19/SUM(E19:F19), 0%) -> 0 | K19: =IF(E19>0, G19/E19,0) -> 0 | L19: =IF(F19>0,H19/F19,0) -> 0 | M19: 0
B20: Viernes | C20: =C19+1 -> 46066 | D20: 0 | E20: 0 | F20: 0 | G20: 0 | H20: 0 | I20: =G20-H20 -> 0 | J20: =IF(SUM(E20:F20),E20/SUM(E20:F20), 0%) -> 0 | K20: =IF(E20>0, G20/E20,0) -> 0 | L20: =IF(F20>0,H20/F20,0) -> 0 | M20: 0
C22: Total semana | D22: =SUM(D16:D20) -> 0 | E22: =SUM(E16:E20) -> 0 | F22: =SUM(F16:F20) -> 0 | G22: =SUM(G16:G20) -> 0 | H22: =SUM(H16:H20) -> 0 | I22: =SUM(I16:I20) -> 0 | J22: =IF(SUM(E22:F22),E22/SUM(E22:F22), 0%) -> 0 | K22: =IF(E22>0, G22/E22,0) -> 0 | L22: =IF(F22>0,H22/F22,0) -> 0 | M22: =SUM(M16:M20) -> 0
A24: 4 | B24: Lunes | C24: =C20+3 -> 46069 | D24: 0 | E24: 0 | F24: 0 | G24: 0 | H24: 0 | I24: =G24-H24 -> 0 | J24: =IF(SUM(E24:F24),E24/SUM(E24:F24), 0%) -> 0 | K24: =IF(E24>0, G24/E24,0) -> 0 | L24: =IF(F24>0,H24/F24,0) -> 0 | M24: 0
B25: Martes | C25: =C24+1 -> 46070 | D25: 0 | E25: 0 | F25: 0 | G25: 0 | H25: 0 | I25: =G25-H25 -> 0 | J25: =IF(SUM(E25:F25),E25/SUM(E25:F25), 0%) -> 0 | K25: =IF(E25>0, G25/E25,0) -> 0 | L25: =IF(F25>0,H25/F25,0) -> 0 | M25: 0
B26: Miércoles | C26: =C25+1 -> 46071 | D26: 0 | E26: 0 | F26: 0 | G26: 0 | H26: 0 | I26: =G26-H26 -> 0 | J26: =IF(SUM(E26:F26),E26/SUM(E26:F26), 0%) -> 0 | K26: =IF(E26>0, G26/E26,0) -> 0 | L26: =IF(F26>0,H26/F26,0) -> 0 | M26: 0
B27: Jueves | C27: =C26+1 -> 46072 | D27: 0 | E27: 0 | F27: 0 | G27: 0 | H27: 0 | I27: =G27-H27 -> 0 | J27: =IF(SUM(E27:F27),E27/SUM(E27:F27), 0%) -> 0 | K27: =IF(E27>0, G27/E27,0) -> 0 | L27: =IF(F27>0,H27/F27,0) -> 0 | M27: 0
B28: Viernes | C28: =C27+1 -> 46073 | D28: 0 | E28: 0 | F28: 0 | G28: 0 | H28: 0 | I28: =G28-H28 -> 0 | J28: =IF(SUM(E28:F28),E28/SUM(E28:F28), 0%) -> 0 | K28: =IF(E28>0, G28/E28,0) -> 0 | L28: =IF(F28>0,H28/F28,0) -> 0 | M28: 0
C30: Total semana | D30: =SUM(D24:D28) -> 0 | E30: =SUM(E24:E28) -> 0 | F30: =SUM(F24:F28) -> 0 | G30: =SUM(G24:G28) -> 0 | H30: =SUM(H24:H28) -> 0 | I30: =SUM(I24:I28) -> 0 | J30: =IF(SUM(E30:F30),E30/SUM(E30:F30), 0%) -> 0 | K30: =IF(E30>0, G30/E30,0) -> 0 | L30: =IF(F30>0,H30/F30,0) -> 0 | M30: =SUM(M24:M28) -> 0
A32: 5 | B32: Lunes | C32: =C28+3 -> 46076 | D32: 0 | E32: 0 | F32: 0 | G32: 0 | H32: 0 | I32: =G32-H32 -> 0 | J32: =IF(SUM(E32:F32),E32/SUM(E32:F32), 0%) -> 0 | K32: =IF(E32>0, G32/E32,0) -> 0 | L32: =IF(F32>0,H32/F32,0) -> 0 | M32: 0
B33: Martes | C33: =C32+1 -> 46077 | D33: 0 | E33: 0 | F33: 0 | G33: 0 | H33: 0 | I33: =G33-H33 -> 0 | J33: =IF(SUM(E33:F33),E33/SUM(E33:F33), 0%) -> 0 | K33: =IF(E33>0, G33/E33,0) -> 0 | L33: =IF(F33>0,H33/F33,0) -> 0 | M33: 0
B34: Miércoles | C34: =C33+1 -> 46078 | D34: 0 | E34: 0 | F34: 0 | G34: 0 | H34: 0 | I34: =G34-H34 -> 0 | J34: =IF(SUM(E34:F34),E34/SUM(E34:F34), 0%) -> 0 | K34: =IF(E34>0, G34/E34,0) -> 0 | L34: =IF(F34>0,H34/F34,0) -> 0 | M34: 0
B35: Jueves | C35: =C34+1 -> 46079 | D35: 0 | E35: 0 | F35: 0 | G35: 0 | H35: 0 | I35: =G35-H35 -> 0 | J35: =IF(SUM(E35:F35),E35/SUM(E35:F35), 0%) -> 0 | K35: =IF(E35>0, G35/E35,0) -> 0 | L35: =IF(F35>0,H35/F35,0) -> 0 | M35: 0
B36: Viernes | C36: =C35+1 -> 46080 | D36: 0 | E36: 0 | F36: 0 | G36: 0 | H36: 0 | I36: =G36-H36 -> 0 | J36: =IF(SUM(E36:F36),E36/SUM(E36:F36), 0%) -> 0 | K36: =IF(E36>0, G36/E36,0) -> 0 | L36: =IF(F36>0,H36/F36,0) -> 0 | M36: 0
C38: Total semana | D38: =SUM(D32:D36) -> 0 | E38: =SUM(E32:E36) -> 0 | F38: =SUM(F32:F36) -> 0 | G38: =SUM(G32:G36) -> 0 | H38: =SUM(H32:H36) -> 0 | I38: =SUM(I32:I36) -> 0 | J38: =IF(SUM(E38:F38),E38/SUM(E38:F38), 0%) -> 0 | K38: =IF(E38>0, G38/E38,0) -> 0 | L38: =IF(F38>0,H38/F38,0) -> 0 | M38: =SUM(M32:M36) -> 0
C40: Total mes | D40: =D14+D30+D22+D38 -> 0 | E40: =E14+E30+E22+E38 -> 0 | F40: =F14+F30+F22+F38 -> 0 | G40: =G14+G30+G22+G38 -> 0 | H40: =H14+H30+H22+H38 -> 0 | I40: =I14+I30+I22+I38 -> 0 | J40: =J14+J30+J22+J38 -> 0 | K40: =K14+K30+K22+K38 -> 0 | L40: =L14+L30+L22+L38 -> 0 | M40: =#REF!+M14+M22+M30+M38 -> #REF!

Sheet Mar
C1: Diligencie unicamente las celdas verdes | F1: Total | G1: Comisiones | I1: Resultado | J1: Balance inicial | K1: =+(K2-J2)/J2 -> 0
C2: Ganancia o perdida del mes | F2: =I48*5*F3 -> 0 | G2: =-D48*D3*F3 -> 0 | I2: =(F2*F3)+G2 -> 0 | J2: 1250 | K2: =I2+J2 -> 1250
C3: Comision | D3: 3 | E3: Cant. Contratos | F3: 1
C6: Fecha | D6: Total Trades | E6: #Ganados | F6: #Perdidos | G6: Puntos ganados | H6: Puntos perdidos | I6: Total puntos | J6: % Gan/Per | K6: Promedio ganancia | L6: Promedio Perdida | O6: Notas y comentarios
A8: 2 | B8: Lunes | C8: 46083 | D8: 0 | E8: 0 | F8: 0 | G8: 0 | H8: 0 | I8: =G8-H8 -> 0 | J8: =IF(SUM(E8:F8),E8/SUM(E8:F8), 0%) -> 0 | K8: =IF(E8>0, G8/E8,0) -> 0 | L8: =IF(F8>0,H8/F8,0) -> 0 | M8: 0
B9: Martes | C9: =C8+1 -> 46084 | D9: 0 | E9: 0 | F9: 0 | G9: 0 | H9: 0 | I9: =G9-H9 -> 0 | J9: =IF(SUM(E9:F9),E9/SUM(E9:F9), 0%) -> 0 | K9: =IF(E9>0, G9/E9,0) -> 0 | L9: =IF(F9>0,H9/F9,0) -> 0 | M9: 0
B10: Miércoles | C10: =C9+1 -> 46085 | D10: 0 | E10: 0 | F10: 0 | G10: 0 | H10: 0 | I10: =G10-H10 -> 0 | J10: =IF(SUM(E10:F10),E10/SUM(E10:F10), 0%) -> 0 | K10: =IF(E10>0, G10/E10,0) -> 0 | L10: =IF(F10>0,H10/F10,0) -> 0 | M10: 0
B11: Jueves | C11: =C10+1 -> 46086 | D11: 0 | E11: 0 | F11: 0 | G11: 0 | H11: 0 | I11: =G11-H11 -> 0 | J11: =IF(SUM(E11:F11),E11/SUM(E11:F11), 0%) -> 0 | K11: =IF(E11>0, G11/E11,0) -> 0 | L11: =IF(F11>0,H11/F11,0) -> 0 | M11: 0
B12: Viernes | C12: =C11+1 -> 46087 | D12: 0 | E12: 0 | F12: 0 | G12: 0 | H12: 0 | I12: =G12-H12 -> 0 | J12: =IF(SUM(E12:F12),E12/SUM(E12:F12), 0%) -> 0 | K12: =IF(E12>0, G12/E12,0) -> 0 | L12: =IF(F12>0,H12/F12,0) -> 0 | M12: 0
C14: Total semana | D14: =SUM(D8:D12) -> 0 | E14: =SUM(E8:E12) -> 0 | F14: =SUM(F8:F12) -> 0 | G14: =SUM(G8:G12) -> 0 | H14: =SUM(H8:H12) -> 0 | I14: =SUM(I8:I12) -> 0 | J14: =IF(SUM(E14:F14),E14/SUM(E14:F14), 0%) -> 0 | K14: =IF(E14>0, G14/E14,0) -> 0 | L14: =IF(F14>0,H14/F14,0) -> 0 | M14: =SUM(M8:M12) -> 0
A16: 3 | B16: Lunes | C16: =C12+3 -> 46090 | D16: 0 | E16: 0 | F16: 0 | G16: 0 | H16: 0 | I16: =G16-H16 -> 0 | J16: =IF(SUM(E16:F16),E16/SUM(E16:F16), 0%) -> 0 | K16: =IF(E16>0, G16/E16,0) -> 0 | L16: =IF(F16>0,H16/F16,0) -> 0 | M16: 0
B17: Martes | C17: =C16+1 -> 46091 | D17: 0 | E17: 0 | F17: 0 | G17: 0 | H17: 0 | I17: =G17-H17 -> 0 | J17: =IF(SUM(E17:F17),E17/SUM(E17:F17), 0%) -> 0 | K17: =IF(E17>0, G17/E17,0) -> 0 | L17: =IF(F17>0,H17/F17,0) -> 0 | M17: 0
B18: Miércoles | C18: =C17+1 -> 46092 | D18: 0 | E18: 0 | F18: 0 | G18: 0 | H18: 0 | I18: =G18-H18 -> 0 | J18: =IF(SUM(E18:F18),E18/SUM(E18:F18), 0%) -> 0 | K18: =IF(E18>0, G18/E18,0) -> 0 | L18: =IF(F18>0,H18/F18,0) -> 0 | M18: 0
B19: Jueves | C19: =C18+1 -> 46093 | D19: 0 | E19: 0 | F19: 0 | G19: 0 | H19: 0 | I19: =G19-H19 -> 0 | J19: =IF(SUM(E19:F19),E19/SUM(E19:F19), 0%) -> 0 | K19: =IF(E19>0, G19/E19,0) -> 0 | L19: =IF(F19>0,H19/F19,0) -> 0 | M19: 0
B20: Viernes | C20: =C19+1 -> 46094 | D20: 0 | E20: 0 | F20: 0 | G20: 0 | H20: 0 | I20: =G20-H20 -> 0 | J20: =IF(SUM(E20:F20),E20/SUM(E20:F20), 0%) -> 0 | K20: =IF(E20>0, G20/E20,0) -> 0 | L20: =IF(F20>0,H20/F20,0) -> 0 | M20: 0
C22: Total semana | D22: =SUM(D16:D20) -> 0 | E22: =SUM(E16:E20) -> 0 | F22: =SUM(F16:F20) -> 0 | G22: =SUM(G16:G20) -> 0 | H22: =SUM(H16:H20) -> 0 | I22: =SUM(I16:I20) -> 0 | J22: =IF(SUM(E22:F22),E22/SUM(E22:F22), 0%) -> 0 | K22: =IF(E22>0, G22/E22,0) -> 0 | L22: =IF(F22>0,H22/F22,0) -> 0 | M22: =SUM(M16:M20) -> 0
A24: 4 | B24: Lunes | C24: =C20+3 -> 46097 | D24: 0 | E24: 0 | F24: 0 | G24: 0 | H24: 0 | I24: =G24-H24 -> 0 | J24: =IF(SUM(E24:F24),E24/SUM(E24:F24), 0%) -> 0 | K24: =IF(E24>0, G24/E24,0) -> 0 | L24: =IF(F24>0,H24/F24,0) -> 0 | M24: 0
B25: Martes | C25: =C24+1 -> 46098 | D25: 0 | E25: 0 | F25: 0 | G25: 0 | H25: 0 | I25: =G25-H25 -> 0 | J25: =IF(SUM(E25:F25),E25/SUM(E25:F25), 0%) -> 0 | K25: =IF(E25>0, G25/E25,0) -> 0 | L25: =IF(F25>0,H25/F25,0) -> 0 | M25: 0
B26: Miércoles | C26: =C25+1 -> 46099 | D26: 0 | E26: 0 | F26: 0 | G26: 0 | H26: 0 | I26: =G26-H26 -> 0 | J26: =IF(SUM(E26:F26),E26/SUM(E26:F26), 0%) -> 0 | K26: =IF(E26>0, G26/E26,0) -> 0 | L26: =IF(F26>0,H26/F26,0) -> 0 | M26: 0
B27: Jueves | C27: =C26+1 -> 46100 | D27: 0 | E27: 0 | F27: 0 | G27: 0 | H27: 0 | I27: =G27-H27 -> 0 | J27: =IF(SUM(E27:F27),E27/SUM(E27:F27), 0%) -> 0 | K27: =IF(E27>0, G27/E27,0) -> 0 | L27: =IF(F27>0,H27/F27,0) -> 0 | M27: 0
B28: Viernes | C28: =C27+1 -> 46101 | D28: 0 | E28: 0 | F28: 0 | G28: 0 | H28: 0 | I28: =G28-H28 -> 0 | J28: =IF(SUM(E28:F28),E28/SUM(E28:F28), 0%) -> 0 | K28: =IF(E28>0, G28/E28,0) -> 0 | L28: =IF(F28>0,H28/F28,0) -> 0 | M28: 0
C30: Total semana | D30: =SUM(D24:D28) -> 0 | E30: =SUM(E24:E28) -> 0 | F30: =SUM(F24:F28) -> 0 | G30: =SUM(G24:G28) -> 0 | H30: =SUM(H24:H28) -> 0 | I30: =SUM(I24:I28) -> 0 | J30: =IF(SUM(E30:F30),E30/SUM(E30:F30), 0%) -> 0 | K30: =IF(E30>0, G30/E30,0) -> 0 | L30: =IF(F30>0,H30/F30,0) -> 0 | M30: =SUM(M24:M28) -> 0
A32: 5 | B32: Lunes | C32: =C28+3 -> 46104 | D32: 0 | E32: 0 | F32: 0 | G32: 0 | H32: 0 | I32: =G32-H32 -> 0 | J32: =IF(SUM(E32:F32),E32/SUM(E32:F32), 0%) -> 0 | K32: =IF(E32>0, G32/E32,0) -> 0 | L32: =IF(F32>0,H32/F32,0) -> 0 | M32: 0
B33: Martes | C33: =C32+1 -> 46105 | D33: 0 | E33: 0 | F33: 0 | G33: 0 | H33: 0 | I33: =G33-H33 -> 0 | J33: =IF(SUM(E33:F33),E33/SUM(E33:F33), 0%) -> 0 | K33: =IF(E33>0, G33/E33,0) -> 0 | L33: =IF(F33>0,H33/F33,0) -> 0 | M33: 0
B34: Miércoles | C34: =C33+1 -> 46106 | D34: 0 | E34: 0 | F34: 0 | G34: 0 | H34: 0 | I34: =G34-H34 -> 0 | J34: =IF(SUM(E34:F34),E34/SUM(E34:F34), 0%) -> 0 | K34: =IF(E34>0, G34/E34,0) -> 0 | L34: =IF(F34>0,H34/F34,0) -> 0 | M34: 0
B35: Jueves | C35: =C34+1 -> 46107 | D35: 0 | E35: 0 | F35: 0 | G35: 0 | H35: 0 | I35: =G35-H35 -> 0 | J35: =IF(SUM(E35:F35),E35/SUM(E35:F35), 0%) -> 0 | K35: =IF(E35>0, G35/E35,0) -> 0 | L35: =IF(F35>0,H35/F35,0) -> 0 | M35: 0
B36: Viernes | C36: =C35+1 -> 46108 | D36: 0 | E36: 0 | F36: 0 | G36: 0 | H36: 0 | I36: =G36-H36 -> 0 | J36: =IF(SUM(E36:F36),E36/SUM(E36:F36), 0%) -> 0 | K36: =IF(E36>0, G36/E36,0) -> 0 | L36: =IF(F36>0,H36/F36,0) -> 0 | M36: 0
C38: Total semana | D38: =SUM(D32:D36) -> 0 | E38: =SUM(E32:E36) -> 0 | F38: =SUM(F32:F36) -> 0 | G38: =SUM(G32:G36) -> 0 | H38: =SUM(H32:H36) -> 0 | I38: =SUM(I32:I36) -> 0 | J38: =IF(SUM(E38:F38),E38/SUM(E38:F38), 0%) -> 0 | K38: =IF(E38>0, G38/E38,0) -> 0 | L38: =IF(F38>0,H38/F38,0) -> 0 | M38: =SUM(M32:M36) -> 0
A40: 5 | B40: Lunes | D40: 0 | E40: 0 | F40: 0 | G40: 0 | H40: 0 | I40: =G40-H40 -> 0 | J40: =IF(SUM(E40:F40),E40/SUM(E40:F40), 0%) -> 0 | K40: =IF(E40>0, G40/E40,0) -> 0 | L40: =IF(F40>0,H40/F40,0) -> 0 | M40: 0
B41: Martes | D41: 0 | E41: 0 | F41: 0 | G41: 0 | H41: 0 | I41: =G41-H41 -> 0 | J41: =IF(SUM(E41:F41),E41/SUM(E41:F41), 0%) -> 0 | K41: =IF(E41>0, G41/E41,0) -> 0 | L41: =IF(F41>0,H41/F41,0) -> 0 | M41: 0
B42: Miércoles | D42: 0 | E42: 0 | F42: 0 | G42: 0 | H42: 0 | I42: =G42-H42 -> 0 | J42: =IF(SUM(E42:F42),E42/SUM(E42:F42), 0%) -> 0 | K42: =IF(E42>0, G42/E42,0) -> 0 | L42: =IF(F42>0,H42/F42,0) -> 0 | M42: 0
B43: Jueves | D43: 0 | E43: 0 | F43: 0 | G43: 0 | H43: 0 | I43: =G43-H43 -> 0 | J43: =IF(SUM(E43:F43),E43/SUM(E43:F43), 0%) -> 0 | K43: =IF(E43>0, G43/E43,0) -> 0 | L43: =IF(F43>0,H43/F43,0) -> 0 | M43: 0
B44: Viernes | D44: 0 | E44: 0 | F44: 0 | G44: 0 | H44: 0 | I44: =G44-H44 -> 0 | J44: =IF(SUM(E44:F44),E44/SUM(E44:F44), 0%) -> 0 | K44: =IF(E44>0, G44/E44,0) -> 0 | L44: =IF(F44>0,H44/F44,0) -> 0 | M44: 0
C46: Total semana | D46: =SUM(D40:D44) -> 0 | E46: =SUM(E40:E44) -> 0 | F46: =SUM(F40:F44) -> 0 | G46: =SUM(G40:G44) -> 0 | H46: =SUM(H40:H44) -> 0 | I46: =SUM(I40:I44) -> 0 | J46: =IF(SUM(E46:F46),E46/SUM(E46:F46), 0%) -> 0 | K46: =IF(E46>0, G46/E46,0) -> 0 | L46: =IF(F46>0,H46/F46,0) -> 0 | M46: =SUM(M40:M44) -> 0
C48: Total mes | D48: =D14+D30+D22+D38+D46 -> 0 | E48: =E14+E30+E22+E38+E46 -> 0 | F48: =F14+F30+F22+F38+F46 -> 0 | G48: =G14+G30+G22+G38+G46 -> 0 | H48: =H14+H30+H22+H38+H46 -> 0 | I48: =I14+I30+I22+I38+I46 -> 0 | J48: =J14+J30+J22+J38+J46 -> 0 | K48: =K14+K30+K22+K38+K46 -> 0 | L48: =L14+L30+L22+L38+L46 -> 0 | M48: =#REF!+M14+M22+M30+M38 -> #REF!

Sheet Abr
C1: Diligencie unicamente las celdas verdes | F1: Total | G1: Comisiones | I1: Resultado | J1: Balance inicial | K1: =+(K2-J2)/J2 -> 0
C2: Ganancia o perdida del mes | F2: =I48*5*F3 -> 0 | G2: =-D48*D3*F3 -> 0 | I2: =(F2*F3)+G2 -> 0 | J2: 1250 | K2: =I2+J2 -> 1250
C3: Comision | D3: 3 | E3: Cant. Contratos | F3: 1
C6: Fecha | D6: Total Trades | E6: #Ganados | F6: #Perdidos | G6: Puntos ganados | H6: Puntos perdidos | I6: Total puntos | J6: % Gan/Per | K6: Promedio ganancia | L6: Promedio Perdida | O6: Notas y comentarios
A8: 1 | B8: Lunes | C8: 46111 | D8: 0 | E8: 0 | F8: 0 | G8: 0 | H8: 0 | I8: =G8-H8 -> 0 | J8: =IF(SUM(E8:F8),E8/SUM(E8:F8), 0%) -> 0 | K8: =IF(E8>0, G8/E8,0) -> 0 | L8: =IF(F8>0,H8/F8,0) -> 0 | M8: 0
B9: Martes | C9: =C8+1 -> 46112 | D9: 0 | E9: 0 | F9: 0 | G9: 0 | H9: 0 | I9: =G9-H9 -> 0 | J9: =IF(SUM(E9:F9),E9/SUM(E9:F9), 0%) -> 0 | K9: =IF(E9>0, G9/E9,0) -> 0 | L9: =IF(F9>0,H9/F9,0) -> 0 | M9: 0
B10: Miércoles | C10: =C9+1 -> 46113 | D10: 0 | E10: 0 | F10: 0 | G10: 0 | H10: 0 | I10: =G10-H10 -> 0 | J10: =IF(SUM(E10:F10),E10/SUM(E10:F10), 0%) -> 0 | K10: =IF(E10>0, G10/E10,0) -> 0 | L10: =IF(F10>0,H10/F10,0) -> 0 | M10: 0
B11: Jueves | C11: =C10+1 -> 46114 | D11: 0 | E11: 0 | F11: 0 | G11: 0 | H11: 0 | I11: =G11-H11 -> 0 | J11: =IF(SUM(E11:F11),E11/SUM(E11:F11), 0%) -> 0 | K11: =IF(E11>0, G11/E11,0) -> 0 | L11: =IF(F11>0,H11/F11,0) -> 0 | M11: 0
B12: Viernes | C12: =C11+1 -> 46115 | D12: 0 | E12: 0 | F12: 0 | G12: 0 | H12: 0 | I12: =G12-H12 -> 0 | J12: =IF(SUM(E12:F12),E12/SUM(E12:F12), 0%) -> 0 | K12: =IF(E12>0, G12/E12,0) -> 0 | L12: =IF(F12>0,H12/F12,0) -> 0 | M12: 0
C14: Total semana | D14: =SUM(D8:D12) -> 0 | E14: =SUM(E8:E12) -> 0 | F14: =SUM(F8:F12) -> 0 | G14: =SUM(G8:G12) -> 0 | H14: =SUM(H8:H12) -> 0 | I14: =SUM(I8:I12) -> 0 | J14: =IF(SUM(E14:F14),E14/SUM(E14:F14), 0%) -> 0 | K14: =IF(E14>0, G14/E14,0) -> 0 | L14: =IF(F14>0,H14/F14,0) -> 0 | M14: =SUM(M8:M12) -> 0
A16: 2 | B16: Lunes | C16: =C12+3 -> 46118 | D16: 0 | E16: 0 | F16: 0 | G16: 0 | H16: 0 | I16: =G16-H16 -> 0 | J16: =IF(SUM(E16:F16),E16/SUM(E16:F16), 0%) -> 0 | K16: =IF(E16>0, G16/E16,0) -> 0 | L16: =IF(F16>0,H16/F16,0) -> 0 | M16: 0
B17: Martes | C17: =C16+1 -> 46119 | D17: 0 | E17: 0 | F17: 0 | G17: 0 | H17: 0 | I17: =G17-H17 -> 0 | J17: =IF(SUM(E17:F17),E17/SUM(E17:F17), 0%) -> 0 | K17: =IF(E17>0, G17/E17,0) -> 0 | L17: =IF(F17>0,H17/F17,0) -> 0 | M17: 0
B18: Miércoles | C18: =C17+1 -> 46120 | D18: 0 | E18: 0 | F18: 0 | G18: 0 | H18: 0 | I18: =G18-H18 -> 0 | J18: =IF(SUM(E18:F18),E18/SUM(E18:F18), 0%) -> 0 | K18: =IF(E18>0, G18/E18,0) -> 0 | L18: =IF(F18>0,H18/F18,0) -> 0 | M18: 0
B19: Jueves | C19: =C18+1 -> 46121 | D19: 0 | E19: 0 | F19: 0 | G19: 0 | H19: 0 | I19: =G19-H19 -> 0 | J19: =IF(SUM(E19:F19),E19/SUM(E19:F19), 0%) -> 0 | K19: =IF(E19>0, G19/E19,0) -> 0 | L19: =IF(F19>0,H19/F19,0) -> 0 | M19: 0
B20: Viernes | C20: =C19+1 -> 46122 | D20: 0 | E20: 0 | F20: 0 | G20: 0 | H20: 0 | I20: =G20-H20 -> 0 | J20: =IF(SUM(E20:F20),E20/SUM(E20:F20), 0%) -> 0 | K20: =IF(E20>0, G20/E20,0) -> 0 | L20: =IF(F20>0,H20/F20,0) -> 0 | M20: 0
C22: Total semana | D22: =SUM(D16:D20) -> 0 | E22: =SUM(E16:E20) -> 0 | F22: =SUM(F16:F20) -> 0 | G22: =SUM(G16:G20) -> 0 | H22: =SUM(H16:H20) -> 0 | I22: =SUM(I16:I20) -> 0 | J22: =IF(SUM(E22:F22),E22/SUM(E22:F22), 0%) -> 0 | K22: =IF(E22>0, G22/E22,0) -> 0 | L22: =IF(F22>0,H22/F22,0) -> 0 | M22: =SUM(M16:M20) -> 0
A24: 3 | B24: Lunes | C24: =C20+3 -> 46125 | D24: 0 | E24: 0 | F24: 0 | G24: 0 | H24: 0 | I24: =G24-H24 -> 0 | J24: =IF(SUM(E24:F24),E24/SUM(E24:F24), 0%) -> 0 | K24: =IF(E24>0, G24/E24,0) -> 0 | L24: =IF(F24>0,H24/F24,0) -> 0 | M24: 0
B25: Martes | C25: =C24+1 -> 46126 | D25: 0 | E25: 0 | F25: 0 | G25: 0 | H25: 0 | I25: =G25-H25 -> 0 | J25: =IF(SUM(E25:F25),E25/SUM(E25:F25), 0%) -> 0 | K25: =IF(E25>0, G25/E25,0) -> 0 | L25: =IF(F25>0,H25/F25,0) -> 0 | M25: 0
B26: Miércoles | C26: =C25+1 -> 46127 | D26: 0 | E26: 0 | F26: 0 | G26: 0 | H26: 0 | I26: =G26-H26 -> 0 | J26: =IF(SUM(E26:F26),E26/SUM(E26:F26), 0%) -> 0 | K26: =IF(E26>0, G26/E26,0) -> 0 | L26: =IF(F26>0,H26/F26,0) -> 0 | M26: 0
B27: Jueves | C27: =C26+1 -> 46128 | D27: 0 | E27: 0 | F27: 0 | G27: 0 | H27: 0 | I27: =G27-H27 -> 0 | J27: =IF(SUM(E27:F27),E27/SUM(E27:F27), 0%) -> 0 | K27: =IF(E27>0, G27/E27,0) -> 0 | L27: =IF(F27>0,H27/F27,0) -> 0 | M27: 0
B28: Viernes | C28: =C27+1 -> 46129 | D28: 0 | E28: 0 | F28: 0 | G28: 0 | H28: 0 | I28: =G28-H28 -> 0 | J28: =IF(SUM(E28:F28),E28/SUM(E28:F28), 0%) -> 0 | K28: =IF(E28>0, G28/E28,0) -> 0 | L28: =IF(F28>0,H28/F28,0) -> 0 | M28: 0
C30: Total semana | D30: =SUM(D24:D28) -> 0 | E30: =SUM(E24:E28) -> 0 | F30: =SUM(F24:F28) -> 0 | G30: =SUM(G24:G28) -> 0 | H30: =SUM(H24:H28) -> 0 | I30: =SUM(I24:I28) -> 0 | J30: =IF(SUM(E30:F30),E30/SUM(E30:F30), 0%) -> 0 | K30: =IF(E30>0, G30/E30,0) -> 0 | L30: =IF(F30>0,H30/F30,0) -> 0 | M30: =SUM(M24:M28) -> 0
A32: 4 | B32: Lunes | C32: =C28+3 -> 46132 | D32: 0 | E32: 0 | F32: 0 | G32: 0 | H32: 0 | I32: =G32-H32 -> 0 | J32: =IF(SUM(E32:F32),E32/SUM(E32:F32), 0%) -> 0 | K32: =IF(E32>0, G32/E32,0) -> 0 | L32: =IF(F32>0,H32/F32,0) -> 0 | M32: 0
B33: Martes | C33: =C32+1 -> 46133 | D33: 0 | E33: 0 | F33: 0 | G33: 0 | H33: 0 | I33: =G33-H33 -> 0 | J33: =IF(SUM(E33:F33),E33/SUM(E33:F33), 0%) -> 0 | K33: =IF(E33>0, G33/E33,0) -> 0 | L33: =IF(F33>0,H33/F33,0) -> 0 | M33: 0
B34: Miércoles | C34: =C33+1 -> 46134 | D34: 0 | E34: 0 | F34: 0 | G34: 0 | H34: 0 | I34: =G34-H34 -> 0 | J34: =IF(SUM(E34:F34),E34/SUM(E34:F34), 0%) -> 0 | K34: =IF(E34>0, G34/E34,0) -> 0 | L34: =IF(F34>0,H34/F34,0) -> 0 | M34: 0
B35: Jueves | C35: =C34+1 -> 46135 | D35: 0 | E35: 0 | F35: 0 | G35: 0 | H35: 0 | I35: =G35-H35 -> 0 | J35: =IF(SUM(E35:F35),E35/SUM(E35:F35), 0%) -> 0 | K35: =IF(E35>0, G35/E35,0) -> 0 | L35: =IF(F35>0,H35/F35,0) -> 0 | M35: 0
B36: Viernes | C36: =C35+1 -> 46136 | D36: 0 | E36: 0 | F36: 0 | G36: 0 | H36: 0 | I36: =G36-H36 -> 0 | J36: =IF(SUM(E36:F36),E36/SUM(E36:F36), 0%) -> 0 | K36: =IF(E36>0, G36/E36,0) -> 0 | L36: =IF(F36>0,H36/F36,0) -> 0 | M36: 0
C38: Total semana | D38: =SUM(D32:D36) -> 0 | E38: =SUM(E32:E36) -> 0 | F38: =SUM(F32:F36) -> 0 | G38: =SUM(G32:G36) -> 0 | H38: =SUM(H32:H36) -> 0 | I38: =SUM(I32:I36) -> 0 | J38: =IF(SUM(E38:F38),E38/SUM(E38:F38), 0%) -> 0 | K38: =IF(E38>0, G38/E38,0) -> 0 | L38: =IF(F38>0,H38/F38,0) -> 0 | M38: =SUM(M32:M36) -> 0
B40: Lunes | C40: =C36+3 -> 46139 | D40: 0 | E40: 0 | F40: 0 | G40: 0 | H40: 0 | I40: =G40-H40 -> 0 | J40: =IF(SUM(E40:F40),E40/SUM(E40:F40), 0%) -> 0 | K40: =IF(E40>0, G40/E40,0) -> 0 | L40: =IF(F40>0,H40/F40,0) -> 0 | M40: 0
B41: Martes | C41: =C40+1 -> 46140 | D41: 0 | E41: 0 | F41: 0 | G41: 0 | H41: 0 | I41: =G41-H41 -> 0 | J41: =IF(SUM(E41:F41),E41/SUM(E41:F41), 0%) -> 0 | K41: =IF(E41>0, G41/E41,0) -> 0 | L41: =IF(F41>0,H41/F41,0) -> 0 | M41: 0
B42: Miércoles | C42: =C41+1 -> 46141 | D42: 0 | E42: 0 | F42: 0 | G42: 0 | H42: 0 | I42: =G42-H42 -> 0 | J42: =IF(SUM(E42:F42),E42/SUM(E42:F42), 0%) -> 0 | K42: =IF(E42>0, G42/E42,0) -> 0 | L42: =IF(F42>0,H42/F42,0) -> 0 | M42: 0
B43: Jueves | C43: =C42+1 -> 46142 | D43: 0 | E43: 0 | F43: 0 | G43: 0 | H43: 0 | I43: =G43-H43 -> 0 | J43: =IF(SUM(E43:F43),E43/SUM(E43:F43), 0%) -> 0 | K43: =IF(E43>0, G43/E43,0) -> 0 | L43: =IF(F43>0,H43/F43,0) -> 0 | M43: 0
B44: Viernes | C44: =C43+1 -> 46143 | D44: 0 | E44: 0 | F44: 0 | G44: 0 | H44: 0 | I44: =G44-H44 -> 0 | J44: =IF(SUM(E44:F44),E44/SUM(E44:F44), 0%) -> 0 | K44: =IF(E44>0, G44/E44,0) -> 0 | L44: =IF(F44>0,H44/F44,0) -> 0 | M44: 0
C46: Total semana | D46: =SUM(D40:D44) -> 0 | E46: =SUM(E40:E44) -> 0 | F46: =SUM(F40:F44) -> 0 | G46: =SUM(G40:G44) -> 0 | H46: =SUM(H40:H44) -> 0 | I46: =SUM(I40:I44) -> 0 | J46: =IF(SUM(E46:F46),E46/SUM(E46:F46), 0%) -> 0 | K46: =IF(E46>0, G46/E46,0) -> 0 | L46: =IF(F46>0,H46/F46,0) -> 0 | M46: =SUM(M40:M44) -> 0
C48: Total mes | D48: =D14+D22+D38+D30 -> 0 | E48: =E14+E22+E38+E30 -> 0 | F48: =F14+F22+F38+F30 -> 0 | G48: =G14+G22+G38+G30 -> 0 | H48: =H14+H22+H38+H30 -> 0 | I48: =I14+I22+I38+I30 -> 0 | J48: =J14+J22+J38+J30+J46 -> 0 | K48: =K14+K22+K38+K30 -> 0 | L48: =L14+L22+L38+L30 -> 0 | M48: =M14+M22+M30+M38+#REF! -> #REF!

Sheet May
C1: Diligencie unicamente las celdas verdes | F1: Total | G1: Comisiones | I1: Resultado | J1: Balance inicial | K1: =+(K2-J2)/J2 -> 0
C2: Ganancia o perdida del mes | F2: =I40*5*F3 -> 0 | G2: =-D40*D3*F3 -> 0 | I2: =(F2*F3)+G2 -> 0 | J2: 1250 | K2: =I2+J2 -> 1250
C3: Comision | D3: 3 | E3: Cant. Contratos | F3: 1
C6: Fecha | D6: Total Trades | E6: #Ganados | F6: #Perdidos | G6: Puntos ganados | H6: Puntos perdidos | I6: Total puntos | J6: % Gan/Per | K6: Promedio ganancia | L6: Promedio Perdida | O6: Notas y comentarios
A8: 2 | B8: Lunes | C8: 46146 | D8: 0 | E8: 0 | F8: 0 | G8: 0 | H8: 0 | I8: =G8-H8 -> 0 | J8: =IF(SUM(E8:F8),E8/SUM(E8:F8), 0%) -> 0 | K8: =IF(E8>0, G8/E8,0) -> 0 | L8: =IF(F8>0,H8/F8,0) -> 0 | M8: 0
B9: Martes | C9: =C8+1 -> 46147 | D9: 0 | E9: 0 | F9: 0 | G9: 0 | H9: 0 | I9: =G9-H9 -> 0 | J9: =IF(SUM(E9:F9),E9/SUM(E9:F9), 0%) -> 0 | K9: =IF(E9>0, G9/E9,0) -> 0 | L9: =IF(F9>0,H9/F9,0) -> 0 | M9: 0
B10: Miércoles | C10: =C9+1 -> 46148 | D10: 0 | E10: 0 | F10: 0 | G10: 0 | H10: 0 | I10: =G10-H10 -> 0 | J10: =IF(SUM(E10:F10),E10/SUM(E10:F10), 0%) -> 0 | K10: =IF(E10>0, G10/E10,0) -> 0 | L10: =IF(F10>0,H10/F10,0) -> 0 | M10: 0
B11: Jueves | C11: =C10+1 -> 46149 | D11: 0 | E11: 0 | F11: 0 | G11: 0 | H11: 0 | I11: =G11-H11 -> 0 | J11: =IF(SUM(E11:F11),E11/SUM(E11:F11), 0%) -> 0 | K11: =IF(E11>0, G11/E11,0) -> 0 | L11: =IF(F11>0,H11/F11,0) -> 0 | M11: 0
B12: Viernes | C12: =C11+1 -> 46150 | D12: 0 | E12: 0 | F12: 0 | G12: 0 | H12: 0 | I12: =G12-H12 -> 0 | J12: =IF(SUM(E12:F12),E12/SUM(E12:F12), 0%) -> 0 | K12: =IF(E12>0, G12/E12,0) -> 0 | L12: =IF(F12>0,H12/F12,0) -> 0 | M12: 0
C14: Total semana | D14: =SUM(D8:D12) -> 0 | E14: =SUM(E8:E12) -> 0 | F14: =SUM(F8:F12) -> 0 | G14: =SUM(G8:G12) -> 0 | H14: =SUM(H8:H12) -> 0 | I14: =SUM(I8:I12) -> 0 | J14: =IF(SUM(E14:F14),E14/SUM(E14:F14), 0%) -> 0 | K14: =IF(E14>0, G14/E14,0) -> 0 | L14: =IF(F14>0,H14/F14,0) -> 0 | M14: =SUM(M8:M12) -> 0
A16: 3 | B16: Lunes | C16: =C12+3 -> 46153 | D16: 0 | E16: 0 | F16: 0 | G16: 0 | H16: 0 | I16: =G16-H16 -> 0 | J16: =IF(SUM(E16:F16),E16/SUM(E16:F16), 0%) -> 0 | K16: =IF(E16>0, G16/E16,0) -> 0 | L16: =IF(F16>0,H16/F16,0) -> 0 | M16: 0
B17: Martes | C17: =C16+1 -> 46154 | D17: 0 | E17: 0 | F17: 0 | G17: 0 | H17: 0 | I17: =G17-H17 -> 0 | J17: =IF(SUM(E17:F17),E17/SUM(E17:F17), 0%) -> 0 | K17: =IF(E17>0, G17/E17,0) -> 0 | L17: =IF(F17>0,H17/F17,0) -> 0 | M17: 0
B18: Miércoles | C18: =C17+1 -> 46155 | D18: 0 | E18: 0 | F18: 0 | G18: 0 | H18: 0 | I18: =G18-H18 -> 0 | J18: =IF(SUM(E18:F18),E18/SUM(E18:F18), 0%) -> 0 | K18: =IF(E18>0, G18/E18,0) -> 0 | L18: =IF(F18>0,H18/F18,0) -> 0 | M18: 0
B19: Jueves | C19: =C18+1 -> 46156 | D19: 0 | E19: 0 | F19: 0 | G19: 0 | H19: 0 | I19: =G19-H19 -> 0 | J19: =IF(SUM(E19:F19),E19/SUM(E19:F19), 0%) -> 0 | K19: =IF(E19>0, G19/E19,0) -> 0 | L19: =IF(F19>0,H19/F19,0) -> 0 | M19: 0
B20: Viernes | C20: =C19+1 -> 46157 | D20: 0 | E20: 0 | F20: 0 | G20: 0 | H20: 0 | I20: =G20-H20 -> 0 | J20: =IF(SUM(E20:F20),E20/SUM(E20:F20), 0%) -> 0 | K20: =IF(E20>0, G20/E20,0) -> 0 | L20: =IF(F20>0,H20/F20,0) -> 0 | M20: 0
C22: Total semana | D22: =SUM(D16:D20) -> 0 | E22: =SUM(E16:E20) -> 0 | F22: =SUM(F16:F20) -> 0 | G22: =SUM(G16:G20) -> 0 | H22: =SUM(H16:H20) -> 0 | I22: =SUM(I16:I20) -> 0 | J22: =IF(SUM(E22:F22),E22/SUM(E22:F22), 0%) -> 0 | K22: =IF(E22>0, G22/E22,0) -> 0 | L22: =IF(F22>0,H22/F22,0) -> 0 | M22: =SUM(M16:M20) -> 0
A24: 4 | B24: Lunes | C24: =C20+3 -> 46160 | D24: 0 | E24: 0 | F24: 0 | G24: 0 | H24: 0 | I24: =G24-H24 -> 0 | J24: =IF(SUM(E24:F24),E24/SUM(E24:F24), 0%) -> 0 | K24: =IF(E24>0, G24/E24,0) -> 0 | L24: =IF(F24>0,H24/F24,0) -> 0 | M24: 0
B25: Martes | C25: =C24+1 -> 46161 | D25: 0 | E25: 0 | F25: 0 | G25: 0 | H25: 0 | I25: =G25-H25 -> 0 | J25: =IF(SUM(E25:F25),E25/SUM(E25:F25), 0%) -> 0 | K25: =IF(E25>0, G25/E25,0) -> 0 | L25: =IF(F25>0,H25/F25,0) -> 0 | M25: 0
B26: Miércoles | C26: =C25+1 -> 46162 | D26: 0 | E26: 0 | F26: 0 | G26: 0 | H26: 0 | I26: =G26-H26 -> 0 | J26: =IF(SUM(E26:F26),E26/SUM(E26:F26), 0%) -> 0 | K26: =IF(E26>0, G26/E26,0) -> 0 | L26: =IF(F26>0,H26/F26,0) -> 0 | M26: 0
B27: Jueves | C27: =C26+1 -> 46163 | D27: 0 | E27: 0 | F27: 0 | G27: 0 | H27: 0 | I27: =G27-H27 -> 0 | J27: =IF(SUM(E27:F27),E27/SUM(E27:F27), 0%) -> 0 | K27: =IF(E27>0, G27/E27,0) -> 0 | L27: =IF(F27>0,H27/F27,0) -> 0 | M27: 0
B28: Viernes | C28: =C27+1 -> 46164 | D28: 0 | E28: 0 | F28: 0 | G28: 0 | H28: 0 | I28: =G28-H28 -> 0 | J28: =IF(SUM(E28:F28),E28/SUM(E28:F28), 0%) -> 0 | K28: =IF(E28>0, G28/E28,0) -> 0 | L28: =IF(F28>0,H28/F28,0) -> 0 | M28: 0
C30: Total semana | D30: =SUM(D24:D28) -> 0 | E30: =SUM(E24:E28) -> 0 | F30: =SUM(F24:F28) -> 0 | G30: =SUM(G24:G28) -> 0 | H30: =SUM(H24:H28) -> 0 | I30: =SUM(I24:I28) -> 0 | J30: =IF(SUM(E30:F30),E30/SUM(E30:F30), 0%) -> 0 | K30: =IF(E30>0, G30/E30,0) -> 0 | L30: =IF(F30>0,H30/F30,0) -> 0 | M30: =SUM(M24:M28) -> 0
A32: 5 | B32: Lunes | C32: =C28+3 -> 46167 | D32: 0 | E32: 0 | F32: 0 | G32: 0 | H32: 0 | I32: =G32-H32 -> 0 | J32: =IF(SUM(E32:F32),E32/SUM(E32:F32), 0%) -> 0 | K32: =IF(E32>0, G32/E32,0) -> 0 | L32: =IF(F32>0,H32/F32,0) -> 0 | M32: 0
B33: Martes | C33: =C32+1 -> 46168 | D33: 0 | E33: 0 | F33: 0 | G33: 0 | H33: 0 | I33: =G33-H33 -> 0 | J33: =IF(SUM(E33:F33),E33/SUM(E33:F33), 0%) -> 0 | K33: =IF(E33>0, G33/E33,0) -> 0 | L33: =IF(F33>0,H33/F33,0) -> 0 | M33: 0
B34: Miércoles | C34: =C33+1 -> 46169 | D34: 0 | E34: 0 | F34: 0 | G34: 0 | H34: 0 | I34: =G34-H34 -> 0 | J34: =IF(SUM(E34:F34),E34/SUM(E34:F34), 0%) -> 0 | K34: =IF(E34>0, G34/E34,0) -> 0 | L34: =IF(F34>0,H34/F34,0) -> 0 | M34: 0
B35: Jueves | C35: =C34+1 -> 46170 | D35: 0 | E35: 0 | F35: 0 | G35: 0 | H35: 0 | I35: =G35-H35 -> 0 | J35: =IF(SUM(E35:F35),E35/SUM(E35:F35), 0%) -> 0 | K35: =IF(E35>0, G35/E35,0) -> 0 | L35: =IF(F35>0,H35/F35,0) -> 0 | M35: 0
B36: Viernes | C36: =C35+1 -> 46171 | D36: 0 | E36: 0 | F36: 0 | G36: 0 | H36: 0 | I36: =G36-H36 -> 0 | J36: =IF(SUM(E36:F36),E36/SUM(E36:F36), 0%) -> 0 | K36: =IF(E36>0, G36/E36,0) -> 0 | L36: =IF(F36>0,H36/F36,0) -> 0 | M36: 0
C38: Total semana | D38: =SUM(D32:D36) -> 0 | E38: =SUM(E32:E36) -> 0 | F38: =SUM(F32:F36) -> 0 | G38: =SUM(G32:G36) -> 0 | H38: =SUM(H32:H36) -> 0 | I38: =SUM(I32:I36) -> 0 | J38: =IF(SUM(E38:F38),E38/SUM(E38:F38), 0%) -> 0 | K38: =IF(E38>0, G38/E38,0) -> 0 | L38: =IF(F38>0,H38/F38,0) -> 0 | M38: =SUM(M32:M36) -> 0
C40: Total mes | D40: =D14+D30+D22+D38 -> 0 | E40: =E14+E30+E22+E38 -> 0 | F40: =F14+F30+F22+F38 -> 0 | G40: =G14+G30+G22+G38 -> 0 | H40: =H14+H30+H22+H38 -> 0 | I40: =I14+I30+I22+I38 -> 0 | J40: =J14+J30+J22+J38 -> 0 | K40: =K14+K30+K22+K38 -> 0 | L40: =L14+L30+L22+L38 -> 0 | M40: =#REF!+M14+M22+M30+M38 -> #REF!

Sheet Jun
C1: Diligencie unicamente las celdas verdes | F1: Total | G1: Comisiones | I1: Resultado | J1: Balance inicial | K1: =+(K2-J2)/J2 -> 0
C2: Ganancia o perdida del mes | F2: =I48*5*F3 -> 0 | G2: =-D48*D3*F3 -> 0 | I2: =(F2*F3)+G2 -> 0 | J2: 1250 | K2: =I2+J2 -> 1250
C3: Comision | D3: 3 | E3: Cant. Contratos | F3: 1
C6: Fecha | D6: Total Trades | E6: #Ganados | F6: #Perdidos | G6: Puntos ganados | H6: Puntos perdidos | I6: Total puntos | J6: % Gan/Per | K6: Promedio ganancia | L6: Promedio Perdida | O6: Notas y comentarios
A8: 1 | B8: Lunes | C8: 46174 | D8: 0 | E8: 0 | F8: 0 | G8: 0 | H8: 0 | I8: =G8-H8 -> 0 | J8: =IF(SUM(E8:F8),E8/SUM(E8:F8), 0%) -> 0 | K8: =IF(E8>0, G8/E8,0) -> 0 | L8: =IF(F8>0,H8/F8,0) -> 0 | M8: 0
B9: Martes | C9: =+C8+1 -> 46175 | D9: 0 | E9: 0 | F9: 0 | G9: 0 | H9: 0 | I9: =G9-H9 -> 0 | J9: =IF(SUM(E9:F9),E9/SUM(E9:F9), 0%) -> 0 | K9: =IF(E9>0, G9/E9,0) -> 0 | L9: =IF(F9>0,H9/F9,0) -> 0 | M9: 0
B10: Miércoles | C10: =+C9+1 -> 46176 | D10: 0 | E10: 0 | F10: 0 | G10: 0 | H10: 0 | I10: =G10-H10 -> 0 | J10: =IF(SUM(E10:F10),E10/SUM(E10:F10), 0%) -> 0 | K10: =IF(E10>0, G10/E10,0) -> 0 | L10: =IF(F10>0,H10/F10,0) -> 0 | M10: 0
B11: Jueves | C11: =+C10+1 -> 46177 | D11: 0 | E11: 0 | F11: 0 | G11: 0 | H11: 0 | I11: =G11-H11 -> 0 | J11: =IF(SUM(E11:F11),E11/SUM(E11:F11), 0%) -> 0 | K11: =IF(E11>0, G11/E11,0) -> 0 | L11: =IF(F11>0,H11/F11,0) -> 0 | M11: 0
B12: Viernes | C12: =+C11+1 -> 46178 | D12: 0 | E12: 0 | F12: 0 | G12: 0 | H12: 0 | I12: =G12-H12 -> 0 | J12: =IF(SUM(E12:F12),E12/SUM(E12:F12), 0%) -> 0 | K12: =IF(E12>0, G12/E12,0) -> 0 | L12: =IF(F12>0,H12/F12,0) -> 0 | M12: 0
C14: Total semana | D14: =SUM(D8:D12) -> 0 | E14: =SUM(E8:E12) -> 0 | F14: =SUM(F8:F12) -> 0 | G14: =SUM(G8:G12) -> 0 | H14: =SUM(H8:H12) -> 0 | I14: =SUM(I8:I12) -> 0 | J14: =IF(SUM(E14:F14),E14/SUM(E14:F14), 0%) -> 0 | K14: =IF(E14>0, G14/E14,0) -> 0 | L14: =IF(F14>0,H14/F14,0) -> 0 | M14: =SUM(M8:M12) -> 0
A16: 2 | B16: Lunes | C16: =+C12+3 -> 46181 | D16: 0 | E16: 0 | F16: 0 | G16: 0 | H16: 0 | I16: =G16-H16 -> 0 | J16: =IF(SUM(E16:F16),E16/SUM(E16:F16), 0%) -> 0 | K16: =IF(E16>0, G16/E16,0) -> 0 | L16: =IF(F16>0,H16/F16,0) -> 0 | M16: 0
B17: Martes | C17: =C16+1 -> 46182 | D17: 0 | E17: 0 | F17: 0 | G17: 0 | H17: 0 | I17: =G17-H17 -> 0 | J17: =IF(SUM(E17:F17),E17/SUM(E17:F17), 0%) -> 0 | K17: =IF(E17>0, G17/E17,0) -> 0 | L17: =IF(F17>0,H17/F17,0) -> 0 | M17: 0
B18: Miércoles | C18: =C17+1 -> 46183 | D18: 0 | E18: 0 | F18: 0 | G18: 0 | H18: 0 | I18: =G18-H18 -> 0 | J18: =IF(SUM(E18:F18),E18/SUM(E18:F18), 0%) -> 0 | K18: =IF(E18>0, G18/E18,0) -> 0 | L18: =IF(F18>0,H18/F18,0) -> 0 | M18: 0
B19: Jueves | C19: =C18+1 -> 46184 | D19: 0 | E19: 0 | F19: 0 | G19: 0 | H19: 0 | I19: =G19-H19 -> 0 | J19: =IF(SUM(E19:F19),E19/SUM(E19:F19), 0%) -> 0 | K19: =IF(E19>0, G19/E19,0) -> 0 | L19: =IF(F19>0,H19/F19,0) -> 0 | M19: 0
B20: Viernes | C20: =C19+1 -> 46185 | D20: 0 | E20: 0 | F20: 0 | G20: 0 | H20: 0 | I20: =G20-H20 -> 0 | J20: =IF(SUM(E20:F20),E20/SUM(E20:F20), 0%) -> 0 | K20: =IF(E20>0, G20/E20,0) -> 0 | L20: =IF(F20>0,H20/F20,0) -> 0 | M20: 0
C22: Total semana | D22: =SUM(D16:D20) -> 0 | E22: =SUM(E16:E20) -> 0 | F22: =SUM(F16:F20) -> 0 | G22: =SUM(G16:G20) -> 0 | H22: =SUM(H16:H20) -> 0 | I22: =SUM(I16:I20) -> 0 | J22: =IF(SUM(E22:F22),E22/SUM(E22:F22), 0%) -> 0 | K22: =IF(E22>0, G22/E22,0) -> 0 | L22: =IF(F22>0,H22/F22,0) -> 0 | M22: =SUM(M16:M20) -> 0
A24: 3 | B24: Lunes | C24: =C20+3 -> 46188 | D24: 0 | E24: 0 | F24: 0 | G24: 0 | H24: 0 | I24: =G24-H24 -> 0 | J24: =IF(SUM(E24:F24),E24/SUM(E24:F24), 0%) -> 0 | K24: =IF(E24>0, G24/E24,0) -> 0 | L24: =IF(F24>0,H24/F24,0) -> 0 | M24: 0
B25: Martes | C25: =C24+1 -> 46189 | D25: 0 | E25: 0 | F25: 0 | G25: 0 | H25: 0 | I25: =G25-H25 -> 0 | J25: =IF(SUM(E25:F25),E25/SUM(E25:F25), 0%) -> 0 | K25: =IF(E25>0, G25/E25,0) -> 0 | L25: =IF(F25>0,H25/F25,0) -> 0 | M25: 0
B26: Miércoles | C26: =C25+1 -> 46190 | D26: 0 | E26: 0 | F26: 0 | G26: 0 | H26: 0 | I26: =G26-H26 -> 0 | J26: =IF(SUM(E26:F26),E26/SUM(E26:F26), 0%) -> 0 | K26: =IF(E26>0, G26/E26,0) -> 0 | L26: =IF(F26>0,H26/F26,0) -> 0 | M26: 0
B27: Jueves | C27: =C26+1 -> 46191 | D27: 0 | E27: 0 | F27: 0 | G27: 0 | H27: 0 | I27: =G27-H27 -> 0 | J27: =IF(SUM(E27:F27),E27/SUM(E27:F27), 0%) -> 0 | K27: =IF(E27>0, G27/E27,0) -> 0 | L27: =IF(F27>0,H27/F27,0) -> 0 | M27: 0
B28: Viernes | C28: =C27+1 -> 46192 | D28: 0 | E28: 0 | F28: 0 | G28: 0 | H28: 0 | I28: =G28-H28 -> 0 | J28: =IF(SUM(E28:F28),E28/SUM(E28:F28), 0%) -> 0 | K28: =IF(E28>0, G28/E28,0) -> 0 | L28: =IF(F28>0,H28/F28,0) -> 0 | M28: 0
C30: Total semana | D30: =SUM(D24:D28) -> 0 | E30: =SUM(E24:E28) -> 0 | F30: =SUM(F24:F28) -> 0 | G30: =SUM(G24:G28) -> 0 | H30: =SUM(H24:H28) -> 0 | I30: =SUM(I24:I28) -> 0 | J30: =IF(SUM(E30:F30),E30/SUM(E30:F30), 0%) -> 0 | K30: =IF(E30>0, G30/E30,0) -> 0 | L30: =IF(F30>0,H30/F30,0) -> 0 | M30: =SUM(M24:M28) -> 0
A32: 4 | B32: Lunes | C32: =C28+3 -> 46195 | D32: 0 | E32: 0 | F32: 0 | G32: 0 | H32: 0 | I32: =G32-H32 -> 0 | J32: =IF(SUM(E32:F32),E32/SUM(E32:F32), 0%) -> 0 | K32: =IF(E32>0, G32/E32,0) -> 0 | L32: =IF(F32>0,H32/F32,0) -> 0 | M32: 0
B33: Martes | C33: =C32+1 -> 46196 | D33: 0 | E33: 0 | F33: 0 | G33: 0 | H33: 0 | I33: =G33-H33 -> 0 | J33: =IF(SUM(E33:F33),E33/SUM(E33:F33), 0%) -> 0 | K33: =IF(E33>0, G33/E33,0) -> 0 | L33: =IF(F33>0,H33/F33,0) -> 0 | M33: 0
B34: Miércoles | C34: =C33+1 -> 46197 | D34: 0 | E34: 0 | F34: 0 | G34: 0 | H34: 0 | I34: =G34-H34 -> 0 | J34: =IF(SUM(E34:F34),E34/SUM(E34:F34), 0%) -> 0 | K34: =IF(E34>0, G34/E34,0) -> 0 | L34: =IF(F34>0,H34/F34,0) -> 0 | M34: 0
B35: Jueves | C35: =C34+1 -> 46198 | D35: 0 | E35: 0 | F35: 0 | G35: 0 | H35: 0 | I35: =G35-H35 -> 0 | J35: =IF(SUM(E35:F35),E35/SUM(E35:F35), 0%) -> 0 | K35: =IF(E35>0, G35/E35,0) -> 0 | L35: =IF(F35>0,H35/F35,0) -> 0 | M35: 0
B36: Viernes | C36: =C35+1 -> 46199 | D36: 0 | E36: 0 | F36: 0 | G36: 0 | H36: 0 | I36: =G36-H36 -> 0 | J36: =IF(SUM(E36:F36),E36/SUM(E36:F36), 0%) -> 0 | K36: =IF(E36>0, G36/E36,0) -> 0 | L36: =IF(F36>0,H36/F36,0) -> 0 | M36: 0
C38: Total semana | D38: =SUM(D32:D36) -> 0 | E38: =SUM(E32:E36) -> 0 | F38: =SUM(F32:F36) -> 0 | G38: =SUM(G32:G36) -> 0 | H38: =SUM(H32:H36) -> 0 | I38: =SUM(I32:I36) -> 0 | J38: =IF(SUM(E38:F38),E38/SUM(E38:F38), 0%) -> 0 | K38: =IF(E38>0, G38/E38,0) -> 0 | L38: =IF(F38>0,H38/F38,0) -> 0 | M38: =SUM(M32:M36) -> 0
A40: 4 | B40: Lunes | C40: =C36+3 -> 46202 | D40: 0 | E40: 0 | F40: 0 | G40: 0 | H40: 0 | I40: =G40-H40 -> 0 | J40: =IF(SUM(E40:F40),E40/SUM(E40:F40), 0%) -> 0 | K40: =IF(E40>0, G40/E40,0) -> 0 | L40: =IF(F40>0,H40/F40,0) -> 0 | M40: 0
B41: Martes | C41: =C40+1 -> 46203 | D41: 0 | E41: 0 | F41: 0 | G41: 0 | H41: 0 | I41: =G41-H41 -> 0 | J41: =IF(SUM(E41:F41),E41/SUM(E41:F41), 0%) -> 0 | K41: =IF(E41>0, G41/E41,0) -> 0 | L41: =IF(F41>0,H41/F41,0) -> 0 | M41: 0
B42: Miércoles | C42: =C41+1 -> 46204 | D42: 0 | E42: 0 | F42: 0 | G42: 0 | H42: 0 | I42: =G42-H42 -> 0 | J42: =IF(SUM(E42:F42),E42/SUM(E42:F42), 0%) -> 0 | K42: =IF(E42>0, G42/E42,0) -> 0 | L42: =IF(F42>0,H42/F42,0) -> 0 | M42: 0
B43: Jueves | C43: =C42+1 -> 46205 | D43: 0 | E43: 0 | F43: 0 | G43: 0 | H43: 0 | I43: =G43-H43 -> 0 | J43: =IF(SUM(E43:F43),E43/SUM(E43:F43), 0%) -> 0 | K43: =IF(E43>0, G43/E43,0) -> 0 | L43: =IF(F43>0,H43/F43,0) -> 0 | M43: 0
B44: Viernes | C44: =C43+1 -> 46206 | D44: 0 | E44: 0 | F44: 0 | G44: 0 | H44: 0 | I44: =G44-H44 -> 0 | J44: =IF(SUM(E44:F44),E44/SUM(E44:F44), 0%) -> 0 | K44: =IF(E44>0, G44/E44,0) -> 0 | L44: =IF(F44>0,H44/F44,0) -> 0 | M44: 0
C46: Total semana | D46: =SUM(D40:D44) -> 0 | E46: =SUM(E40:E44) -> 0 | F46: =SUM(F40:F44) -> 0 | G46: =SUM(G40:G44) -> 0 | H46: =SUM(H40:H44) -> 0 | I46: =SUM(I40:I44) -> 0 | J46: =IF(SUM(E46:F46),E46/SUM(E46:F46), 0%) -> 0 | K46: =IF(E46>0, G46/E46,0) -> 0 | L46: =IF(F46>0,H46/F46,0) -> 0 | M46: =SUM(M40:M44) -> 0
C48: Total mes | D48: =D14+D22+D38+D30+D46 -> 0 | E48: =E14+E22+E38+E30+E46 -> 0 | F48: =F14+F22+F38+F30+F46 -> 0 | G48: =G14+G22+G38+G30+G46 -> 0 | H48: =H14+H22+H38+H30+H46 -> 0 | I48: =I14+I22+I38+I30+I46 -> 0 | J48: =J14+J22+J38+J30+J46 -> 0 | K48: =K14+K22+K38+K30+K46 -> 0 | L48: =L14+L22+L38+L30+L46 -> 0 | M48: =M14+M22+M30+M38+#REF! -> #REF!

Sheet Jul
C1: Diligencie unicamente las celdas verdes | F1: Total | G1: Comisiones | I1: Resultado | J1: Balance inicial | K1: =+(K2-J2)/J2 -> 0
C2: Ganancia o perdida del mes | F2: =I41*5*F3 -> 0 | G2: =-D41*D3*F3 -> 0 | I2: =(F2*F3)+G2 -> 0 | J2: 1250 | K2: =I2+J2 -> 1250
C3: Comision | D3: 3 | E3: Cant. Contratos | F3: 1
C6: Fecha | D6: Total Trades | E6: #Ganados | F6: #Perdidos | G6: Puntos ganados | H6: Puntos perdidos | I6: Total puntos | J6: % Gan/Per | K6: Promedio ganancia | L6: Promedio Perdida | O6: Notas y comentarios
A8: 1 | B8: Lunes | C8: 46209 | D8: 0 | E8: 0 | F8: 0 | G8: 0 | H8: 0 | I8: =G8-H8 -> 0 | J8: =IF(SUM(E8:F8),E8/SUM(E8:F8), 0%) -> 0 | K8: =IF(E8>0, G8/E8,0) -> 0 | L8: =IF(F8>0,H8/F8,0) -> 0 | M8: 0
B9: Martes | C9: =+C8+1 -> 46210 | D9: 0 | E9: 0 | F9: 0 | G9: 0 | H9: 0 | I9: =G9-H9 -> 0 | J9: =IF(SUM(E9:F9),E9/SUM(E9:F9), 0%) -> 0 | K9: =IF(E9>0, G9/E9,0) -> 0 | L9: =IF(F9>0,H9/F9,0) -> 0 | M9: 0
B10: Miércoles | C10: =C9+1 -> 46211 | D10: 0 | E10: 0 | F10: 0 | G10: 0 | H10: 0 | I10: =G10-H10 -> 0 | J10: =IF(SUM(E10:F10),E10/SUM(E10:F10), 0%) -> 0 | K10: =IF(E10>0, G10/E10,0) -> 0 | L10: =IF(F10>0,H10/F10,0) -> 0 | M10: 0
B11: Jueves | C11: =C10+1 -> 46212 | D11: 0 | E11: 0 | F11: 0 | G11: 0 | H11: 0 | I11: =G11-H11 -> 0 | J11: =IF(SUM(E11:F11),E11/SUM(E11:F11), 0%) -> 0 | K11: =IF(E11>0, G11/E11,0) -> 0 | L11: =IF(F11>0,H11/F11,0) -> 0 | M11: 0
B12: Viernes | C12: =C11+1 -> 46213 | D12: 0 | E12: 0 | F12: 0 | G12: 0 | H12: 0 | I12: =G12-H12 -> 0 | J12: =IF(SUM(E12:F12),E12/SUM(E12:F12), 0%) -> 0 | K12: =IF(E12>0, G12/E12,0) -> 0 | L12: =IF(F12>0,H12/F12,0) -> 0 | M12: 0
C14: Total semana | D14: =SUM(D8:D12) -> 0 | E14: =SUM(E8:E12) -> 0 | F14: =SUM(F8:F12) -> 0 | G14: =SUM(G8:G12) -> 0 | H14: =SUM(H8:H12) -> 0 | I14: =SUM(I8:I12) -> 0 | J14: =IF(SUM(E14:F14),E14/SUM(E14:F14), 0%) -> 0 | K14: =IF(E14>0, G14/E14,0) -> 0 | L14: =IF(F14>0,H14/F14,0) -> 0 | M14: =SUM(M8:M12) -> 0
A16: 2 | B16: Lunes | C16: =+C12+3 -> 46216 | D16: 0 | E16: 0 | F16: 0 | G16: 0 | H16: 0 | I16: =G16-H16 -> 0 | J16: =IF(SUM(E16:F16),E16/SUM(E16:F16), 0%) -> 0 | K16: =IF(E16>0, G16/E16,0) -> 0 | L16: =IF(F16>0,H16/F16,0) -> 0 | M16: 0
B17: Martes | C17: =C16+1 -> 46217 | D17: 0 | E17: 0 | F17: 0 | G17: 0 | H17: 0 | I17: =G17-H17 -> 0 | J17: =IF(SUM(E17:F17),E17/SUM(E17:F17), 0%) -> 0 | K17: =IF(E17>0, G17/E17,0) -> 0 | L17: =IF(F17>0,H17/F17,0) -> 0 | M17: 0
B18: Miércoles | C18: =C17+1 -> 46218 | D18: 0 | E18: 0 | F18: 0 | G18: 0 | H18: 0 | I18: =G18-H18 -> 0 | J18: =IF(SUM(E18:F18),E18/SUM(E18:F18), 0%) -> 0 | K18: =IF(E18>0, G18/E18,0) -> 0 | L18: =IF(F18>0,H18/F18,0) -> 0 | M18: 0
B19: Jueves | C19: =C18+1 -> 46219 | D19: 0 | E19: 0 | F19: 0 | G19: 0 | H19: 0 | I19: =G19-H19 -> 0 | J19: =IF(SUM(E19:F19),E19/SUM(E19:F19), 0%) -> 0 | K19: =IF(E19>0, G19/E19,0) -> 0 | L19: =IF(F19>0,H19/F19,0) -> 0 | M19: 0
B20: Viernes | C20: =C19+1 -> 46220 | D20: 0 | E20: 0 | F20: 0 | G20: 0 | H20: 0 | I20: =G20-H20 -> 0 | J20: =IF(SUM(E20:F20),E20/SUM(E20:F20), 0%) -> 0 | K20: =IF(E20>0, G20/E20,0) -> 0 | L20: =IF(F20>0,H20/F20,0) -> 0 | M20: 0
C22: Total semana | D22: =SUM(D16:D20) -> 0 | E22: =SUM(E16:E20) -> 0 | F22: =SUM(F16:F20) -> 0 | G22: =SUM(G16:G20) -> 0 | H22: =SUM(H16:H20) -> 0 | I22: =SUM(I16:I20) -> 0 | J22: =IF(SUM(E22:F22),E22/SUM(E22:F22), 0%) -> 0 | K22: =IF(E22>0, G22/E22,0) -> 0 | L22: =IF(F22>0,H22/F22,0) -> 0 | M22: =SUM(M16:M20) -> 0
A24: 3 | B24: Lunes | C24: =C20+3 -> 46223 | D24: 0 | E24: 0 | F24: 0 | G24: 0 | H24: 0 | I24: =G24-H24 -> 0 | J24: =IF(SUM(E24:F24),E24/SUM(E24:F24), 0%) -> 0 | K24: =IF(E24>0, G24/E24,0) -> 0 | L24: =IF(F24>0,H24/F24,0) -> 0 | M24: 0
B25: Martes | C25: =C24+1 -> 46224 | D25: 0 | E25: 0 | F25: 0 | G25: 0 | H25: 0 | I25: =G25-H25 -> 0 | J25: =IF(SUM(E25:F25),E25/SUM(E25:F25), 0%) -> 0 | K25: =IF(E25>0, G25/E25,0) -> 0 | L25: =IF(F25>0,H25/F25,0) -> 0 | M25: 0
B26: Miércoles | C26: =C25+1 -> 46225 | D26: 0 | E26: 0 | F26: 0 | G26: 0 | H26: 0 | I26: =G26-H26 -> 0 | J26: =IF(SUM(E26:F26),E26/SUM(E26:F26), 0%) -> 0 | K26: =IF(E26>0, G26/E26,0) -> 0 | L26: =IF(F26>0,H26/F26,0) -> 0 | M26: 0
B27: Jueves | C27: =C26+1 -> 46226 | D27: 0 | E27: 0 | F27: 0 | G27: 0 | H27: 0 | I27: =G27-H27 -> 0 | J27: =IF(SUM(E27:F27),E27/SUM(E27:F27), 0%) -> 0 | K27: =IF(E27>0, G27/E27,0) -> 0 | L27: =IF(F27>0,H27/F27,0) -> 0 | M27: 0
B28: Viernes | C28: =C27+1 -> 46227 | D28: 0 | E28: 0 | F28: 0 | G28: 0 | H28: 0 | I28: =G28-H28 -> 0 | J28: =IF(SUM(E28:F28),E28/SUM(E28:F28), 0%) -> 0 | K28: =IF(E28>0, G28/E28,0) -> 0 | L28: =IF(F28>0,H28/F28,0) -> 0 | M28: 0
C30: Total semana | D30: =SUM(D24:D28) -> 0 | E30: =SUM(E24:E28) -> 0 | F30: =SUM(F24:F28) -> 0 | G30: =SUM(G24:G28) -> 0 | H30: =SUM(H24:H28) -> 0 | I30: =SUM(I24:I28) -> 0 | J30: =IF(SUM(E30:F30),E30/SUM(E30:F30), 0%) -> 0 | K30: =IF(E30>0, G30/E30,0) -> 0 | L30: =IF(F30>0,H30/F30,0) -> 0 | M30: =SUM(M24:M28) -> 0
A32: 4 | B32: Lunes | C32: =C28+3 -> 46230 | D32: 0 | E32: 0 | F32: 0 | G32: 0 | H32: 0 | I32: =G32-H32 -> 0 | J32: =IF(SUM(E32:F32),E32/SUM(E32:F32), 0%) -> 0 | K32: =IF(E32>0, G32/E32,0) -> 0 | L32: =IF(F32>0,H32/F32,0) -> 0 | M32: 0
B33: Martes | C33: =C32+1 -> 46231 | D33: 0 | E33: 0 | F33: 0 | G33: 0 | H33: 0 | I33: =G33-H33 -> 0 | J33: =IF(SUM(E33:F33),E33/SUM(E33:F33), 0%) -> 0 | K33: =IF(E33>0, G33/E33,0) -> 0 | L33: =IF(F33>0,H33/F33,0) -> 0 | M33: 0
B34: Miércoles | C34: =C33+1 -> 46232 | D34: 0 | E34: 0 | F34: 0 | G34: 0 | H34: 0 | I34: =G34-H34 -> 0 | J34: =IF(SUM(E34:F34),E34/SUM(E34:F34), 0%) -> 0 | K34: =IF(E34>0, G34/E34,0) -> 0 | L34: =IF(F34>0,H34/F34,0) -> 0 | M34: 0
B35: Jueves | C35: =C34+1 -> 46233 | D35: 0 | E35: 0 | F35: 0 | G35: 0 | H35: 0 | I35: =G35-H35 -> 0 | J35: =IF(SUM(E35:F35),E35/SUM(E35:F35), 0%) -> 0 | K35: =IF(E35>0, G35/E35,0) -> 0 | L35: =IF(F35>0,H35/F35,0) -> 0 | M35: 0
B36: Viernes | C36: =C35+1 -> 46234 | D36: 0 | E36: 0 | F36: 0 | G36: 0 | H36: 0 | I36: =G36-H36 -> 0 | J36: =IF(SUM(E36:F36),E36/SUM(E36:F36), 0%) -> 0 | K36: =IF(E36>0, G36/E36,0) -> 0 | L36: =IF(F36>0,H36/F36,0) -> 0 | M36: 0
C38: Total semana | D38: =SUM(D32:D36) -> 0 | E38: =SUM(E32:E36) -> 0 | F38: =SUM(F32:F36) -> 0 | G38: =SUM(G32:G36) -> 0 | H38: =SUM(H32:H36) -> 0 | I38: =SUM(I32:I36) -> 0 | J38: =IF(SUM(E38:F38),E38/SUM(E38:F38), 0%) -> 0 | K38: =IF(E38>0, G38/E38,0) -> 0 | L38: =IF(F38>0,H38/F38,0) -> 0 | M38: =SUM(M32:M36) -> 0
C41: Total mes | D41: =D14+D22+D38+D30 -> 0 | E41: =E14+E22+E38+E30 -> 0 | F41: =F14+F22+F38+F30 -> 0 | G41: =G14+G22+G38+G30 -> 0 | H41: =H14+H22+H38+H30 -> 0 | I41: =I14+I22+I38+I30 -> 0 | J41: =J14+J22+J38+J30 -> 0 | K41: =K14+K22+K38+K30 -> 0 | L41: =L14+L22+L38+L30 -> 0 | M41: =M14+M22+M30+M38+#REF! -> #REF!

Sheet Ago
C1: Diligencie unicamente las celdas verdes | F1: Total | G1: Comisiones | I1: Resultado | J1: Balance inicial | K1: =+(K2-J2)/J2 -> 0
C2: Ganancia o perdida del mes | F2: =I42*5*F3 -> 0 | G2: =-D42*D3*F3 -> 0 | I2: =(F2*F3)+G2 -> 0 | J2: 1250 | K2: =I2+J2 -> 1250
C3: Comision | D3: 3 | E3: Cant. Contratos | F3: 1
C6: Fecha | D6: Total Trades | E6: #Ganados | F6: #Perdidos | G6: Puntos ganados | H6: Puntos perdidos | I6: Total puntos | J6: % Gan/Per | K6: Promedio ganancia | L6: Promedio Perdida | O6: Notas y comentarios
A8: 2 | B8: Lunes | C8: 46237 | D8: 0 | E8: 0 | F8: 0 | G8: 0 | H8: 0 | I8: =G8-H8 -> 0 | J8: =IF(SUM(E8:F8),E8/SUM(E8:F8), 0%) -> 0 | K8: =IF(E8>0, G8/E8,0) -> 0 | L8: =IF(F8>0,H8/F8,0) -> 0 | M8: 0
B9: Martes | C9: =C8+1 -> 46238 | D9: 0 | E9: 0 | F9: 0 | G9: 0 | H9: 0 | I9: =G9-H9 -> 0 | J9: =IF(SUM(E9:F9),E9/SUM(E9:F9), 0%) -> 0 | K9: =IF(E9>0, G9/E9,0) -> 0 | L9: =IF(F9>0,H9/F9,0) -> 0 | M9: 0
B10: Miércoles | C10: =C9+1 -> 46239 | D10: 0 | E10: 0 | F10: 0 | G10: 0 | H10: 0 | I10: =G10-H10 -> 0 | J10: =IF(SUM(E10:F10),E10/SUM(E10:F10), 0%) -> 0 | K10: =IF(E10>0, G10/E10,0) -> 0 | L10: =IF(F10>0,H10/F10,0) -> 0 | M10: 0
B11: Jueves | C11: =C10+1 -> 46240 | D11: 0 | E11: 0 | F11: 0 | G11: 0 | H11: 0 | I11: =G11-H11 -> 0 | J11: =IF(SUM(E11:F11),E11/SUM(E11:F11), 0%) -> 0 | K11: =IF(E11>0, G11/E11,0) -> 0 | L11: =IF(F11>0,H11/F11,0) -> 0 | M11: 0
B12: Viernes | C12: =C11+1 -> 46241 | D12: 0 | E12: 0 | F12: 0 | G12: 0 | H12: 0 | I12: =G12-H12 -> 0 | J12: =IF(SUM(E12:F12),E12/SUM(E12:F12), 0%) -> 0 | K12: =IF(E12>0, G12/E12,0) -> 0 | L12: =IF(F12>0,H12/F12,0) -> 0 | M12: 0
C14: Total semana | D14: =SUM(D8:D12) -> 0 | E14: =SUM(E8:E12) -> 0 | F14: =SUM(F8:F12) -> 0 | G14: =SUM(G8:G12) -> 0 | H14: =SUM(H8:H12) -> 0 | I14: =SUM(I8:I12) -> 0 | J14: =IF(SUM(E14:F14),E14/SUM(E14:F14), 0%) -> 0 | K14: =IF(E14>0, G14/E14,0) -> 0 | L14: =IF(F14>0,H14/F14,0) -> 0 | M14: =SUM(M8:M12) -> 0
A16: 3 | B16: Lunes | C16: =C12+3 -> 46244 | D16: 0 | E16: 0 | F16: 0 | G16: 0 | H16: 0 | I16: =G16-H16 -> 0 | J16: =IF(SUM(E16:F16),E16/SUM(E16:F16), 0%) -> 0 | K16: =IF(E16>0, G16/E16,0) -> 0 | L16: =IF(F16>0,H16/F16,0) -> 0 | M16: 0
B17: Martes | C17: =C16+1 -> 46245 | D17: 0 | E17: 0 | F17: 0 | G17: 0 | H17: 0 | I17: =G17-H17 -> 0 | J17: =IF(SUM(E17:F17),E17/SUM(E17:F17), 0%) -> 0 | K17: =IF(E17>0, G17/E17,0) -> 0 | L17: =IF(F17>0,H17/F17,0) -> 0 | M17: 0
B18: Miércoles | C18: =C17+1 -> 46246 | D18: 0 | E18: 0 | F18: 0 | G18: 0 | H18: 0 | I18: =G18-H18 -> 0 | J18: =IF(SUM(E18:F18),E18/SUM(E18:F18), 0%) -> 0 | K18: =IF(E18>0, G18/E18,0) -> 0 | L18: =IF(F18>0,H18/F18,0) -> 0 | M18: 0
B19: Jueves | C19: =C18+1 -> 46247 | D19: 0 | E19: 0 | F19: 0 | G19: 0 | H19: 0 | I19: =G19-H19 -> 0 | J19: =IF(SUM(E19:F19),E19/SUM(E19:F19), 0%) -> 0 | K19: =IF(E19>0, G19/E19,0) -> 0 | L19: =IF(F19>0,H19/F19,0) -> 0 | M19: 0
B20: Viernes | C20: =C19+1 -> 46248 | D20: 0 | E20: 0 | F20: 0 | G20: 0 | H20: 0 | I20: =G20-H20 -> 0 | J20: =IF(SUM(E20:F20),E20/SUM(E20:F20), 0%) -> 0 | K20: =IF(E20>0, G20/E20,0) -> 0 | L20: =IF(F20>0,H20/F20,0) -> 0 | M20: 0
C22: Total semana | D22: =SUM(D16:D20) -> 0 | E22: =SUM(E16:E20) -> 0 | F22: =SUM(F16:F20) -> 0 | G22: =SUM(G16:G20) -> 0 | H22: =SUM(H16:H20) -> 0 | I22: =SUM(I16:I20) -> 0 | J22: =IF(SUM(E22:F22),E22/SUM(E22:F22), 0%) -> 0 | K22: =IF(E22>0, G22/E22,0) -> 0 | L22: =IF(F22>0,H22/F22,0) -> 0 | M22: =SUM(M16:M20) -> 0
A24: 4 | B24: Lunes | C24: =C20+3 -> 46251 | D24: 0 | E24: 0 | F24: 0 | G24: 0 | H24: 0 | I24: =G24-H24 -> 0 | J24: =IF(SUM(E24:F24),E24/SUM(E24:F24), 0%) -> 0 | K24: =IF(E24>0, G24/E24,0) -> 0 | L24: =IF(F24>0,H24/F24,0) -> 0 | M24: 0
B25: Martes | C25: =C24+1 -> 46252 | D25: 0 | E25: 0 | F25: 0 | G25: 0 | H25: 0 | I25: =G25-H25 -> 0 | J25: =IF(SUM(E25:F25),E25/SUM(E25:F25), 0%) -> 0 | K25: =IF(E25>0, G25/E25,0) -> 0 | L25: =IF(F25>0,H25/F25,0) -> 0 | M25: 0
B26: Miércoles | C26: =C25+1 -> 46253 | D26: 0 | E26: 0 | F26: 0 | G26: 0 | H26: 0 | I26: =G26-H26 -> 0 | J26: =IF(SUM(E26:F26),E26/SUM(E26:F26), 0%) -> 0 | K26: =IF(E26>0, G26/E26,0) -> 0 | L26: =IF(F26>0,H26/F26,0) -> 0 | M26: 0
B27: Jueves | C27: =C26+1 -> 46254 | D27: 0 | E27: 0 | F27: 0 | G27: 0 | H27: 0 | I27: =G27-H27 -> 0 | J27: =IF(SUM(E27:F27),E27/SUM(E27:F27), 0%) -> 0 | K27: =IF(E27>0, G27/E27,0) -> 0 | L27: =IF(F27>0,H27/F27,0) -> 0 | M27: 0
B28: Viernes | C28: =C27+1 -> 46255 | D28: 0 | E28: 0 | F28: 0 | G28: 0 | H28: 0 | I28: =G28-H28 -> 0 | J28: =IF(SUM(E28:F28),E28/SUM(E28:F28), 0%) -> 0 | K28: =IF(E28>0, G28/E28,0) -> 0 | L28: =IF(F28>0,H28/F28,0) -> 0 | M28: 0
C30: Total semana | D30: =SUM(D24:D28) -> 0 | E30: =SUM(E24:E28) -> 0 | F30: =SUM(F24:F28) -> 0 | G30: =SUM(G24:G28) -> 0 | H30: =SUM(H24:H28) -> 0 | I30: =SUM(I24:I28) -> 0 | J30: =IF(SUM(E30:F30),E30/SUM(E30:F30), 0%) -> 0 | K30: =IF(E30>0, G30/E30,0) -> 0 | L30: =IF(F30>0,H30/F30,0) -> 0 | M30: =SUM(M24:M28) -> 0
A32: 5 | B32: Lunes | C32: =C28+3 -> 46258 | D32: 0 | E32: 0 | F32: 0 | G32: 0 | H32: 0 | I32: =G32-H32 -> 0 | J32: =IF(SUM(E32:F32),E32/SUM(E32:F32), 0%) -> 0 | K32: =IF(E32>0, G32/E32,0) -> 0 | L32: =IF(F32>0,H32/F32,0) -> 0 | M32: 0
B33: Martes | C33: =C32+1 -> 46259 | D33: 0 | E33: 0 | F33: 0 | G33: 0 | H33: 0 | I33: =G33-H33 -> 0 | J33: =IF(SUM(E33:F33),E33/SUM(E33:F33), 0%) -> 0 | K33: =IF(E33>0, G33/E33,0) -> 0 | L33: =IF(F33>0,H33/F33,0) -> 0 | M33: 0
B34: Miércoles | C34: =C33+1 -> 46260 | D34: 0 | E34: 0 | F34: 0 | G34: 0 | H34: 0 | I34: =G34-H34 -> 0 | J34: =IF(SUM(E34:F34),E34/SUM(E34:F34), 0%) -> 0 | K34: =IF(E34>0, G34/E34,0) -> 0 | L34: =IF(F34>0,H34/F34,0) -> 0 | M34: 0
B35: Jueves | C35: =+C34+1 -> 46261 | D35: 0 | E35: 0 | F35: 0 | G35: 0 | H35: 0 | I35: =G35-H35 -> 0 | J35: =IF(SUM(E35:F35),E35/SUM(E35:F35), 0%) -> 0 | K35: =IF(E35>0, G35/E35,0) -> 0 | L35: =IF(F35>0,H35/F35,0) -> 0 | M35: 0
B36: Viernes | C36: =+C35+1 -> 46262 | D36: 0 | E36: 0 | F36: 0 | G36: 0 | H36: 0 | I36: =G36-H36 -> 0 | J36: =IF(SUM(E36:F36),E36/SUM(E36:F36), 0%) -> 0 | K36: =IF(E36>0, G36/E36,0) -> 0 | L36: =IF(F36>0,H36/F36,0) -> 0 | M36: 0
C38: Total semana | D38: =SUM(D32:D36) -> 0 | E38: =SUM(E32:E36) -> 0 | F38: =SUM(F32:F36) -> 0 | G38: 0 | H38: =SUM(H32:H36) -> 0 | I38: =SUM(I32:I36) -> 0 | J38: =IF(SUM(E38:F38),E38/SUM(E38:F38), 0%) -> 0 | K38: =IF(E38>0, G38/E38,0) -> 0 | L38: =IF(F38>0,H38/F38,0) -> 0 | M38: =SUM(M32:M36) -> 0
C42: Total mes | D42: =D14+D30+D22+D38+D40 -> 0 | E42: =E14+E30+E22+E38+E40 -> 0 | F42: =F14+F30+F22+F38+F40 -> 0 | G42: =G14+G30+G22+G38+G40 -> 0 | H42: =H14+H30+H22+H38+H40 -> 0 | I42: =I14+I30+I22+I38+I40 -> 0 | J42: =J14+J30+J22+J38 -> 0 | K42: =K14+K30+K22+K38+K40 -> 0 | L42: =L14+L30+L22+L38+L40 -> 0 | M42: =#REF!+M14+M22+M30+M38 -> #REF!

Sheet Sep
C1: Diligencie unicamente las celdas verdes | F1: Total | G1: Comisiones | I1: Resultado | J1: Balance inicial | K1: =+(K2-J2)/J2 -> 0
C2: Ganancia o perdida del mes | F2: =I48*5*F3 -> 0 | G2: =-D48*D3*F3 -> 0 | I2: =(F2*F3)+G2 -> 0 | J2: 1250 | K2: =I2+J2 -> 1250
C3: Comision | D3: 3 | E3: Cant. Contratos | F3: 1
C6: Fecha | D6: Total Trades | E6: #Ganados | F6: #Perdidos | G6: Puntos ganados | H6: Puntos perdidos | I6: Total puntos | J6: % Gan/Per | K6: Promedio ganancia | L6: Promedio Perdida | O6: Notas y comentarios
A8: 1 | B8: Lunes | C8: 46265 | D8: 0 | E8: 0 | F8: 0 | G8: 0 | H8: 0 | I8: =G8-H8 -> 0 | J8: =IF(SUM(E8:F8),E8/SUM(E8:F8), 0%) -> 0 | K8: =IF(E8>0, G8/E8,0) -> 0 | L8: =IF(F8>0,H8/F8,0) -> 0 | M8: 0
